Workbook

Sheet Inputs
A2: AVESTA — Case Inputs | J2: Selected consumption and bill
A3: Edit the yellow cells. Location is fixed at Cairo. Initial values are the previous El Mo3alem example, not new measurements. | J3: Input status | L3: =IF(OR(C10<=0,COUNT(C10)=0),"Enter billing days",IF(AND(C6<>"Bill only",OR(C7<0,COUNT(C7)=0)),"Enter consumption",IF(AND(C6<>"Consumption only",OR(C8<0,COUNT(C8)=0)),"Enter bill amount",IF(AND(C6="Bill only",C66<>1),"Bill does not give a unique consumption",IF(AND(C14="Specified",OR(C15<=0,COUNT(C15)=0)),"Enter a positive area",IF(AND(C17="Known",OR(C18<0,C18>1,COUNT(C18)=0)),"Check daytime share",IF(AND(C20="Known",OR(C21<=0,COUNT(C21)=0)),"Enter a positive critical load","Ready for indicative calculation"))))))) -> Ready for indicative calculation
J4: Selected monthly use (kWh) | L4: =IF(L3<>"Ready for indicative calculation","Not available",IF(C6="Bill only",SUM(G50:G63),C7)) -> 2421
A5: Case name | C5: El Mo3alem shop — example | J5: Average consumption (kWh/day) | L5: =IF(ISNUMBER(L4),L4/C10,"Not available") -> 80.7
A6: Input mode | C6: Bill and consumption | J6: Active daytime energy share | L6: =IF(C17="Known",C18,'Assumptions and Catalog'!$C$13/24) -> 0.5
A7: Monthly consumption (kWh) | C7: 2421 | E7: Monthly use, not the cumulative meter reading | J7: Reference official bill (EGP) | L7: =IF(ISNUMBER(L4),IF(Inputs!$C$9="Residential",IF(L4<='Assumptions and Catalog'!$C$50,L4*'Assumptions and Catalog'!$H$50+'Assumptions and Catalog'!$E$50+'Assumptions and Catalog'!$F$50,IF(L4<='Assumptions and Catalog'!$C$51,L4*'Assumptions and Catalog'!$H$51+'Assumptions and Catalog'!$E$51+'Assumptions and Catalog'!$F$51,IF(L4<='Assumptions and Catalog'!$C$52,L4*'Assumptions and Catalog'!$H$52+'Assumptions and Catalog'!$E$52+'Assumptions and Catalog'!$F$52,IF(L4<='Assumptions and Catalog'!$C$53,L4*'Assumptions and Catalog'!$H$53+'Assumptions and Catalog'!$E$53+'Assumptions and Catalog'!$F$53,IF(L4<='Assumptions and Catalog'!$C$54,L4*'Assumptions and Catalog'!$H$54+'Assumptions and Catalog'!$E$54+'Assumptions and Catalog'!$F$54,IF(L4<='Assumptions and Catalog'!$C$55,L4*'Assumptions and Catalog'!$H$55+'Assumptions and Catalog'!$E$55+'Assumptions and Catalog'!$F$55,IF(L4<='Assumptions and Catalog'!$C$56,L4*'Assumptions and Catalog'!$H$56+'Assumptions and Catalog'!$E$56+'Assumptions and Catalog'!$F$56,IF(L4<='Assumptions and Catalog'!$C$57,L4*'Assumptions and Catalog'!$H$57+'Assumptions and Catalog'!$E$57+'Assumptions and Catalog'!$F$57,"Out of range")))))))),IF(L4<='Assumptions and Catalog'!$C$60,L4*'Assumptions and Catalog'!$H$60+'Assumptions and Catalog'!$E$60+'Assumptions and Catalog'!$F$60,IF(L4<='Assumptions and Catalog'!$C$61,L4*'Assumptions and Catalog'!$H$61+'Assumptions and Catalog'!$E$61+'Assumptions and Catalog'!$F$61,IF(L4<='Assumptions and Catalog'!$C$62,L4*'Assumptions and Catalog'!$H$62+'Assumptions and Catalog'!$E$62+'Assumptions and Catalog'!$F$62,IF(L4<='Assumptions and Catalog'!$C$63,L4*'Assumptions and Catalog'!$H$63+'Assumptions and Catalog'!$E$63+'Assumptions and Catalog'!$F$63,IF(L4<='Assumptions and Catalog'!$C$64,L4*'Assumptions and Catalog'!$H$64+'Assumptions and Catalog'!$E$64+'Assumptions and Catalog'!$F$64,IF(L4<='Assumptions and Catalog'!$C$65,L4*'Assumptions and Catalog'!$H$65+'Assumptions and Catalog'!$E$65+'Assumptions and Catalog'!$F$65,"Out of range"))))))),"Not available") -> 6867.22
A8: Monthly bill amount (EGP) | C8: 8279 | E8: Consumption bill, not a prepaid top-up | J8: Paid less official bill (EGP) | L8: =IF(AND(C6="Bill and consumption",ISNUMBER(L7)),C8-L7,"Not available") -> 1411.78
A9: Tariff category | C9: Commercial | J9: Active pricing basis | L9: =IF(AND(C6="Bill and consumption",C7>0,C11="Actual flat rate"),"Actual flat rate","Official") -> Official
A10: Billing period days | C10: 30 | J10: Actual average (EGP/kWh) | L10: =IF(AND(C6="Bill and consumption",C7>0),C8/C7,"Not available") -> 3.4196613
A11: Pricing basis | C11: Official | E11: Actual flat rate is available only with both bill amount and consumption | J11: Official average (EGP/kWh) | L11: =IF(AND(ISNUMBER(L4),L4>0),L7/L4,"Not available") -> 2.8365221
J12: Average rate difference (EGP/kWh) | L12: =IF(AND(ISNUMBER(L10),ISNUMBER(L11)),L10-L11,"Not available") -> 0.5831392
J13: Selected baseline bill (EGP) | L13: =IF(ISNUMBER(L4),IF(L9="Actual flat rate",L4*L10,L7),"Not available") -> 6867.22
A14: Available installation area | C14: Unspecified | J14: Reference-data status | L14: ="Reference tariffs and prices: verify before commercial use" -> Reference tariffs and prices: verify before commercial use
A15: Available area (m2) | C15: 50 | E15: Usable installation area after obstacles; unspecified area sets no cap
A17: Energy distribution | C17: Constant load
A18: Daytime energy share | C18: 0.5 | E18: Share of energy, not appliance count; night share is calculated
A20: Critical load | C20: Unknown
A21: Critical load (kW) | C21: 4 | E21: When unknown, no customer-specific backup hours are calculated
A39: Enter the case inputs, review assumptions, then choose equipment and quantities on the Scenarios sheet.
A40: Actual flat rate spreads the paid bill over kWh; it may differ from the marginal cost of avoided electricity.
A41: One representative day/night cycle per month with constant daily load. This is not an hourly simulation.
A47: Inverse-bill calculations — audit detail
A49: Tariff | B49: Above | C49: Up to | D49: Candidate kWh | E49: Candidate bill | F49: Valid solution 1/0 | G49: Accepted kWh
A50: ='Assumptions and Catalog'!$A$50 -> Residential | B50: ='Assumptions and Catalog'!$B$50 -> -1 | C50: ='Assumptions and Catalog'!$C$50 -> 0 | D50: =IF('Assumptions and Catalog'!$H$50=0,0,($C$8-'Assumptions and Catalog'!$E$50-'Assumptions and Catalog'!$F$50)/'Assumptions and Catalog'!$H$50) -> 0 | E50: =D50*'Assumptions and Catalog'!$H$50+'Assumptions and Catalog'!$E$50+'Assumptions and Catalog'!$F$50 -> 9 | F50: =IF(AND(A50=$C$9,D50>B50,D50<=C50,D50>=0,ABS(E50-$C$8)<='Assumptions and Catalog'!$C$25),1,0) -> 0 | G50: =IF(F50=1,D50,0) -> 0
A51: ='Assumptions and Catalog'!$A$51 -> Residential | B51: ='Assumptions and Catalog'!$B$51 -> 0 | C51: ='Assumptions and Catalog'!$C$51 -> 50 | D51: =IF('Assumptions and Catalog'!$H$51=0,0,($C$8-'Assumptions and Catalog'!$E$51-'Assumptions and Catalog'!$F$51)/'Assumptions and Catalog'!$H$51) -> 12173.529 | E51: =D51*'Assumptions and Catalog'!$H$51+'Assumptions and Catalog'!$E$51+'Assumptions and Catalog'!$F$51 -> 8279 | F51: =IF(AND(A51=$C$9,D51>B51,D51<=C51,D51>=0,ABS(E51-$C$8)<='Assumptions and Catalog'!$C$25),1,0) -> 0 | G51: =IF(F51=1,D51,0) -> 0
A52: ='Assumptions and Catalog'!$A$52 -> Residential | B52: ='Assumptions and Catalog'!$B$52 -> 50 | C52: ='Assumptions and Catalog'!$C$52 -> 100 | D52: =IF('Assumptions and Catalog'!$H$52=0,0,($C$8-'Assumptions and Catalog'!$E$52-'Assumptions and Catalog'!$F$52)/'Assumptions and Catalog'!$H$52) -> 9524.7126 | E52: =D52*'Assumptions and Catalog'!$H$52+'Assumptions and Catalog'!$E$52+'Assumptions and Catalog'!$F$52 -> 8279 | F52: =IF(AND(A52=$C$9,D52>B52,D52<=C52,D52>=0,ABS(E52-$C$8)<='Assumptions and Catalog'!$C$25),1,0) -> 0 | G52: =IF(F52=1,D52,0) -> 0
A53: ='Assumptions and Catalog'!$A$53 -> Residential | B53: ='Assumptions and Catalog'!$B$53 -> 100 | C53: ='Assumptions and Catalog'!$C$53 -> 200 | D53: =IF('Assumptions and Catalog'!$H$53=0,0,($C$8-'Assumptions and Catalog'!$E$53-'Assumptions and Catalog'!$F$53)/'Assumptions and Catalog'!$H$53) -> 8273 | E53: =D53*'Assumptions and Catalog'!$H$53+'Assumptions and Catalog'!$E$53+'Assumptions and Catalog'!$F$53 -> 8279 | F53: =IF(AND(A53=$C$9,D53>B53,D53<=C53,D53>=0,ABS(E53-$C$8)<='Assumptions and Catalog'!$C$25),1,0) -> 0 | G53: =IF(F53=1,D53,0) -> 0
A54: ='Assumptions and Catalog'!$A$54 -> Residential | B54: ='Assumptions and Catalog'!$B$54 -> 200 | C54: ='Assumptions and Catalog'!$C$54 -> 350 | D54: =IF('Assumptions and Catalog'!$H$54=0,0,($C$8-'Assumptions and Catalog'!$E$54-'Assumptions and Catalog'!$F$54)/'Assumptions and Catalog'!$H$54) -> 4863.5838 | E54: =D54*'Assumptions and Catalog'!$H$54+'Assumptions and Catalog'!$E$54+'Assumptions and Catalog'!$F$54 -> 8279 | F54: =IF(AND(A54=$C$9,D54>B54,D54<=C54,D54>=0,ABS(E54-$C$8)<='Assumptions and Catalog'!$C$25),1,0) -> 0 | G54: =IF(F54=1,D54,0) -> 0
A55: ='Assumptions and Catalog'!$A$55 -> Residential | B55: ='Assumptions and Catalog'!$B$55 -> 350 | C55: ='Assumptions and Catalog'!$C$55 -> 650 | D55: =IF('Assumptions and Catalog'!$H$55=0,0,($C$8-'Assumptions and Catalog'!$E$55-'Assumptions and Catalog'!$F$55)/'Assumptions and Catalog'!$H$55) -> 3930.0459 | E55: =D55*'Assumptions and Catalog'!$H$55+'Assumptions and Catalog'!$E$55+'Assumptions and Catalog'!$F$55 -> 8279 | F55: =IF(AND(A55=$C$9,D55>B55,D55<=C55,D55>=0,ABS(E55-$C$8)<='Assumptions and Catalog'!$C$25),1,0) -> 0 | G55: =IF(F55=1,D55,0) -> 0
A56: ='Assumptions and Catalog'!$A$56 -> Residential | B56: ='Assumptions and Catalog'!$B$56 -> 650 | C56: ='Assumptions and Catalog'!$C$56 -> 1000 | D56: =IF('Assumptions and Catalog'!$H$56=0,0,($C$8-'Assumptions and Catalog'!$E$56-'Assumptions and Catalog'!$F$56)/'Assumptions and Catalog'!$H$56) -> 3512.3404 | E56: =D56*'Assumptions and Catalog'!$H$56+'Assumptions and Catalog'!$E$56+'Assumptions and Catalog'!$F$56 -> 8279 | F56: =IF(AND(A56=$C$9,D56>B56,D56<=C56,D56>=0,ABS(E56-$C$8)<='Assumptions and Catalog'!$C$25),1,0) -> 0 | G56: =IF(F56=1,D56,0) -> 0
A57: ='Assumptions and Catalog'!$A$57 -> Residential | B57: ='Assumptions and Catalog'!$B$57 -> 1000 | C57: ='Assumptions and Catalog'!$C$57 -> 10000000 | D57: =IF('Assumptions and Catalog'!$H$57=0,0,($C$8-'Assumptions and Catalog'!$E$57-'Assumptions and Catalog'!$F$57)/'Assumptions and Catalog'!$H$57) -> 2850.8651 | E57: =D57*'Assumptions and Catalog'!$H$57+'Assumptions and Catalog'!$E$57+'Assumptions and Catalog'!$F$57 -> 8279 | F57: =IF(AND(A57=$C$9,D57>B57,D57<=C57,D57>=0,ABS(E57-$C$8)<='Assumptions and Catalog'!$C$25),1,0) -> 0 | G57: =IF(F57=1,D57,0) -> 0
A58: ='Assumptions and Catalog'!$A$60 -> Commercial | B58: ='Assumptions and Catalog'!$B$60 -> -1 | C58: ='Assumptions and Catalog'!$C$60 -> 0 | D58: =IF('Assumptions and Catalog'!$H$60=0,0,($C$8-'Assumptions and Catalog'!$E$60-'Assumptions and Catalog'!$F$60)/'Assumptions and Catalog'!$H$60) -> 0 | E58: =D58*'Assumptions and Catalog'!$H$60+'Assumptions and Catalog'!$E$60+'Assumptions and Catalog'!$F$60 -> 9 | F58: =IF(AND(A58=$C$9,D58>B58,D58<=C58,D58>=0,ABS(E58-$C$8)<='Assumptions and Catalog'!$C$25),1,0) -> 0 | G58: =IF(F58=1,D58,0) -> 0
A59: ='Assumptions and Catalog'!$A$61 -> Commercial | B59: ='Assumptions and Catalog'!$B$61 -> 0 | C59: ='Assumptions and Catalog'!$C$61 -> 100 | D59: =IF('Assumptions and Catalog'!$H$61=0,0,($C$8-'Assumptions and Catalog'!$E$61-'Assumptions and Catalog'!$F$61)/'Assumptions and Catalog'!$H$61) -> 5014.5455 | E59: =D59*'Assumptions and Catalog'!$H$61+'Assumptions and Catalog'!$E$61+'Assumptions and Catalog'!$F$61 -> 8279 | F59: =IF(AND(A59=$C$9,D59>B59,D59<=C59,D59>=0,ABS(E59-$C$8)<='Assumptions and Catalog'!$C$25),1,0) -> 0 | G59: =IF(F59=1,D59,0) -> 0
A60: ='Assumptions and Catalog'!$A$62 -> Commercial | B60: ='Assumptions and Catalog'!$B$62 -> 100 | C60: ='Assumptions and Catalog'!$C$62 -> 250 | D60: =IF('Assumptions and Catalog'!$H$62=0,0,($C$8-'Assumptions and Catalog'!$E$62-'Assumptions and Catalog'!$F$62)/'Assumptions and Catalog'!$H$62) -> 3773.516 | E60: =D60*'Assumptions and Catalog'!$H$62+'Assumptions and Catalog'!$E$62+'Assumptions and Catalog'!$F$62 -> 8279 | F60: =IF(AND(A60=$C$9,D60>B60,D60<=C60,D60>=0,ABS(E60-$C$8)<='Assumptions and Catalog'!$C$25),1,0) -> 0 | G60: =IF(F60=1,D60,0) -> 0
A61: ='Assumptions and Catalog'!$A$63 -> Commercial | B61: ='Assumptions and Catalog'!$B$63 -> 250 | C61: ='Assumptions and Catalog'!$C$63 -> 600 | D61: =IF('Assumptions and Catalog'!$H$63=0,0,($C$8-'Assumptions and Catalog'!$E$63-'Assumptions and Catalog'!$F$63)/'Assumptions and Catalog'!$H$63) -> 3093.2584 | E61: =D61*'Assumptions and Catalog'!$H$63+'Assumptions and Catalog'!$E$63+'Assumptions and Catalog'!$F$63 -> 8279 | F61: =IF(AND(A61=$C$9,D61>B61,D61<=C61,D61>=0,ABS(E61-$C$8)<='Assumptions and Catalog'!$C$25),1,0) -> 0 | G61: =IF(F61=1,D61,0) -> 0
A62: ='Assumptions and Catalog'!$A$64 -> Commercial | B62: ='Assumptions and Catalog'!$B$64 -> 600 | C62: ='Assumptions and Catalog'!$C$64 -> 1000 | D62: =IF('Assumptions and Catalog'!$H$64=0,0,($C$8-'Assumptions and Catalog'!$E$64-'Assumptions and Catalog'!$F$64)/'Assumptions and Catalog'!$H$64) -> 3001.444 | E62: =D62*'Assumptions and Catalog'!$H$64+'Assumptions and Catalog'!$E$64+'Assumptions and Catalog'!$F$64 -> 8279 | F62: =IF(AND(A62=$C$9,D62>B62,D62<=C62,D62>=0,ABS(E62-$C$8)<='Assumptions and Catalog'!$C$25),1,0) -> 0 | G62: =IF(F62=1,D62,0) -> 0
A63: ='Assumptions and Catalog'!$A$65 -> Commercial | B63: ='Assumptions and Catalog'!$B$65 -> 1000 | C63: ='Assumptions and Catalog'!$C$65 -> 10000000 | D63: =IF('Assumptions and Catalog'!$H$65=0,0,($C$8-'Assumptions and Catalog'!$E$65-'Assumptions and Catalog'!$F$65)/'Assumptions and Catalog'!$H$65) -> 2921.6312 | E63: =D63*'Assumptions and Catalog'!$H$65+'Assumptions and Catalog'!$E$65+'Assumptions and Catalog'!$F$65 -> 8279 | F63: =IF(AND(A63=$C$9,D63>B63,D63<=C63,D63>=0,ABS(E63-$C$8)<='Assumptions and Catalog'!$C$25),1,0) -> 1 | G63: =IF(F63=1,D63,0) -> 2921.6312
A66: Accepted solution count | C66: =SUM(F50:F63) -> 1

Sheet Assumptions and Catalog
A2: AVESTA — Assumptions and Catalog
A3: Yellow cells are editable. Equipment prices and limits are illustrative, not supplier quotes or manufacturer specifications.
A6: Study period | B6: years | C6: 10 | D6: 1 to 20
A7: Nominal discount rate | B7: % | C7: 0.1 | D7: Illustrative assumption; approval needed
A8: Tariff and fee escalation | B8: % per year | C8: 0 | D8: Flat by default; applies to all bill components
A9: Maintenance cost escalation | B9: % per year | C9: 0 | D9: Assumed cost escalation
A10: Annual PV degradation | B10: % per year | C10: 0.005 | D10: Assumption
A11: Charge efficiency | B11: % | C11: 0.975 | D11: AC input to stored energy
A12: Discharge efficiency | B12: % | C12: 0.975 | D12: Stored energy to AC load
A13: Daytime duration | B13: hours/day | C13: 12 | D13: Not PSH; used only to split daily load
A14: PV charging window | B14: hours/day | C14: 6 | D14: Approximate power window, not hourly simulation
A15: Grid charging window | B15: hours/day | C15: 8 | D15: Battery-only scenario
A16: Installation area multiplier | B16: times panel area | C16: 1.5 | D16: Includes assumed installation clearances
A17: Installation and BOS | B17: % of equipment | C17: 0.1 | D17: Applied once to PV, battery and inverter
... A26: Battery auxiliary consumption | B26: kWh/day | C26: 0 | D26: Not estimated; enter standby consumption
A29: Cairo seasonal solar production - experimental
A31: Annual-average PV yield (derived) | B31: kWh/kWp/day | C31: ='Solar Production'!D32 -> 4.9818356 | D31: Derived summary only. Monthly calculations use Solar Production.
A33: Monthly yield from Solar Production replaces the fixed daily average in this trial.
A34: Edit tilt and compass azimuth on Solar Production. PVGIS losses are already included.
A35: Source: JRC PVGIS 5.3 / SARAH3, 2005-2023; retrieved 26 October 2026.
A36: https://re.jrc.ec.europa.eu/pvg_tools/en/
A46: Editable reference tariff bands
A47: Tariffs from prior project files; current applicability could not be confirmed from the regulator link. Verify before commercial use.
A49: Type | B49: Above kWh | C49: Up to kWh | D49: Energy rate | E49: Energy intercept | F49: Service fee (EGP) | G49: Stamp/kWh | H49: Marginal rate incl. stamp
A50: Residential | B50: -1 | C50: 0 | D50: 0 | E50: 0 | F50: 9 | G50: 0 | H50: =D50+G50 -> 0
A51: Residential | B51: 0 | C51: 50 | D51: 0.68 | E51: 0 | F51: 1 | G51: 0 | H51: =D51+G51 -> 0.68
A52: Residential | B52: 50 | C52: 100 | D52: 0.87 | E52: =C51*D51-C51*D52 -> -9.5 | F52: 2 | G52: 0 | H52: =D52+G52 -> 0.87
A53: Residential | B53: 100 | C53: 200 | D53: 1 | E53: 0 | F53: 6 | G53: 0 | H53: =D53+G53 -> 1
A54: Residential | B54: 200 | C54: 350 | D54: 1.73 | E54: =C53*D53-C53*D54 -> -146 | F54: 11 | G54: 0 | H54: =D54+G54 -> 1.73
A55: Residential | B55: 350 | C55: 650 | D55: 2.18 | E55: =C54*D54+E54-C54*D55 -> -303.5 | F55: 15 | G55: 0 | H55: =D55+G55 -> 2.18
A56: Residential | B56: 650 | C56: 1000 | D56: 2.35 | E56: 0 | F56: 25 | G56: 0 | H56: =D56+G56 -> 2.35
A57: Residential | B57: 1000 | C57: 10000000 | D57: 2.89 | E57: 0 | F57: 40 | G57: 0 | H57: =D57+G57 -> 2.89
A60: Commercial | B60: -1 | C60: 0 | D60: 0 | E60: 0 | F60: 9 | G60: 0 | H60: =D60+G60 -> 0
A61: Commercial | B61: 0 | C61: 100 | D61: 1.62 | E61: 0 | F61: 5 | G61: 0.03 | H61: =D61+G61 -> 1.65
A62: Commercial | B62: 100 | C62: 250 | D62: 2.16 | E62: 0 | F62: 15 | G62: 0.03 | H62: =D62+G62 -> 2.19
A63: Commercial | B63: 250 | C63: 600 | D63: 2.64 | E63: 0 | F63: 20 | G63: 0.03 | H63: =D63+G63 -> 2.67
A64: Commercial | B64: 600 | C64: 1000 | D64: 2.74 | E64: =C63*D63-C63*D64 -> -60 | F64: 25 | G64: 0.03 | H64: =D64+G64 -> 2.77
A65: Commercial | B65: 1000 | C65: 10000000 | D65: 2.79 | E65: 0 | F65: 40 | G65: 0.03 | H65: =D65+G65 -> 2.82
A67: Residential rates: prior project model; service fees require confirmation. Commercial: prior El Mo3alem presentation (April 2026).
A68: https://www.egyptera.org/ar/TarrifApril2026.aspx — verification on 19 October 2026 returned 404. Annual stamp excluded.
...

Sheet Scenarios
A2: AVESTA — Scenario Comparison | W2: El Mo3alem - eight source scenarios | AH2: Shared assumptions and reproduction notes
A3: Three manually selected configurations. Financial results are indicative; no automatic size optimization. | W3: STATIC SNAPSHOTS - captured 22 Oct 2026. These results do not update automatically. Re-run and verify each scenario after changing any recorded input or assumption.
W4: Scenario | Y4: Scenario 1 | Z4: Scenario 2 | AA4: Scenario 3 | AB4: Scenario 4 | AC4: Scenario 5 | AD4: Scenario 6 | AE4: Scenario 7 | AF4: Scenario 8 | AH4: Capture date | AK4: 2026-10-22
A5: Metric | B5: Unit | C5: Solar only | D5: Battery only | E5: Solar and battery | W5: Source design | Y5: 25 kW solar only | Z5: 10 kWh battery | AA5: 10 m2 + 10 kWh | AB5: 25 m2 + 10 kWh | AC5: 50 m2 + 20 kWh | AD5: 10 m2 + 30 kWh | AE5: 50 m2 + 50 kWh | AF5: 10 m2 + 50 kWh | AH5: Recalculation engine | AK5: LibreOffice; every case recalculated before capture
A6: Configuration status | C6: =IF(COUNTIFS(C926:C980,"ERROR:*")>0,"ERROR - see C926:C980",IF(COUNTIFS(C926:C980,"WARNING:*")>0,"Valid with warnings - see checks","Valid for indicative calculation")) -> Valid with warnings - see checks | D6: =IF(COUNTIFS(G926:G980,"ERROR:*")>0,"ERROR - see G926:G980",IF(COUNTIFS(G926:G980,"WARNING:*")>0,"Valid with warnings - see checks","Valid for indicative calculation")) -> Valid with warnings - see checks | E6: =IF(COUNTIFS(K926:K980,"ERROR:*")>0,"ERROR - see K926:K980",IF(COUNTIFS(K926:K980,"WARNING:*")>0,"Valid with warnings - see checks","Valid for indicative calculation")) -> Valid with warnings - see checks | W6: Model column | Y6: Solar only | Z6: Battery only | AA6: Solar and battery | AB6: Solar and battery | AC6: Solar and battery | AD6: Solar and battery | AE6: Solar and battery | AF6: Solar and battery | AH6: Consumption source | AK6: Verified receipt: 2,421 kWh and EGP 8,279. August 2026.
A7: PV capacity | B7: kWp | C7: =C51 -> 8.8 | D7: =D51 -> 0 | E7: =E51 -> 11 | H7: Equipment and quantities — edit yellow cells | W7: Implemented scope | Y7: PV self-use; no export | Z7: Backup only | AA7: PV self-use + backup | AB7: PV self-use + backup | AC7: PV self-use + backup | AD7: Partial: PV + backup | AE7: Partial: PV + backup | AF7: Partial: PV + backup | AH7: Billing interval | AK7: 30-day planning assumption; actual interval unconfirmed
A8: Nominal battery capacity | B8: kWh | C8: =C52 -> 0 | D8: =D52 -> 16 | E8: =E52 -> 16 | H8: Setting | I8: Unit | J8: Solar only | K8: Battery only | L8: Solar and battery | W8: Design status | Y8: Roof / hardware unverified | Z8: Backup overload (3 < 4 kW) | AA8: Roof conflict | AB8: Roof conflict | AC8: Roof conflict | AD8: Roof conflict; scope incomplete | AE8: Roof conflict; scope incomplete | AF8: Roof conflict; scope incomplete | AH8: Forecast calendar start | AK8: 2027
A9: Inverter capacity | B9: kW | C9: =C53 -> 10 | D9: =D53 -> 5 | E9: =E53 -> 12 | H9: Panel model | J9: PV550 | K9: PV550 | L9: PV550 | W9: Manager document location | Y9: PART 3 / SCENARIO 1 | Z9: PART 3 / SCENARIO 2 | AA9: PART 3 / SCENARIO 3 | AB9: PART 3 / SCENARIO 4 | AC9: PART 3 / SCENARIO 5 | AD9: PART 3 / SCENARIO 6 | AE9: PART 3 / SCENARIO 7 | AF9: PART 3 / SCENARIO 8 | AH9: Study period (years) | AK9: 10
A10: Required roof area | B10: m² | C10: =C59 -> 62.4 | D10: =D59 -> 0 | E10: =E59 -> 78 | H10: Panel quantity | J10: 16 | K10: 0 | L10: 20 | W10: Recorded inputs and equipment | AH10: Discount rate | AK10: 0.1
A11: Initial investment | B11: EGP | C11: =C64 -> 143440 | D11: =D64 -> 273064 | E11: =E64 -> 416064 | H11: Battery model | J11: BAT16 | K11: BAT16 | L11: BAT16 | W11: Input mode | Y11: Bill and consumption | Z11: Bill and consumption | AA11: Bill and consumption | AB11: Bill and consumption | AC11: Bill and consumption | AD11: Bill and consumption | AE11: Bill and consumption | AF11: Bill and consumption | AH11: Tariff escalation | AK11: 0
A12: Year 1 solar generation | B12: kWh | C12: =SUM(F161:F172) -> 16001.656 | D12: =SUM(F411:F422) -> 0 | E12: =SUM(F661:F672) -> 20002.07 | H12: Battery unit quantity | J12: 0 | K12: 1 | L12: 1 | W12: Measured monthly consumption | X12: kWh | Y12: 2421 | Z12: 2421 | AA12: 2421 | AB12: 2421 | AC12: 2421 | AD12: 2421 | AE12: 2421 | AF12: 2421 | AH12: Cost escalation | AK12: 0
A13: Year 1 baseline bill | B13: EGP | C13: =$B$79 -> 83544.51 | D13: =$B$79 -> 83544.51 | E13: =$B$79 -> 83544.51 | H13: Inverter model | J13: GRID10 | K13: HYB5 | L13: HYB12 | W13: Recorded monthly payment | X13: EGP | Y13: 8279 | Z13: 8279 | AA13: 8279 | AB13: 8279 | AC13: 8279 | AD13: 8279 | AE13: 8279 | AF13: 8279 | AH13: PV degradation per year | AK13: 0.005
A14: Year 1 bill after installation | B14: EGP | C14: =IF(C65=1,SUM(N161:N172),"Invalid") -> 42587.264 | D14: =IF(D65=1,SUM(N411:N422),"Invalid") -> 83544.51 | E14: =IF(E65=1,SUM(N661:N672),"Invalid") -> 31310.42 | H14: Reserved share of usable capacity | I14: % | J14: 0.2 | K14: 1 | L14: 0.2 | W14: Billing period (planning assumption) | X14: days | Y14: 30 | Z14: 30 | AA14: 30 | AB14: 30 | AC14: 30 | AD14: 30 | AE14: 30 | AF14: 30 | AH14: Charge efficiency | AK14: 0.975
A15: Year 1 bill savings | B15: EGP | C15: =IF(C65=1,SUM(O161:O172),"Invalid") -> 40957.246 | D15: =IF(D65=1,SUM(O411:O422),"Invalid") -> 0 | E15: =IF(E65=1,SUM(O661:O672),"Invalid") -> 52234.09 | H15: Battery-only operating mode | J15: Backup | K15: Backup | L15: Backup | W15: Tariff type | Y15: Commercial | Z15: Commercial | AA15: Commercial | AB15: Commercial | AC15: Commercial | AD15: Commercial | AE15: Commercial | AF15: Commercial | AH15: Discharge efficiency | AK15: 0.975
A16: Year 1 savings after maintenance | B16: EGP | C16: =IF(C65=1,C79,"Invalid") -> 39522.846 | D16: =IF(D65=1,G79,"Invalid") -> -2730.64 | E16: =IF(E65=1,K79,"Invalid") -> 48073.45 | H16: Grid-charged delivery limit | I16: kWh/day | J16: 8 | K16: 8 | L16: 8 | W16: Pricing basis | Y16: Official reference tariff | Z16: Official reference tariff | AA16: Official reference tariff | AB16: Official reference tariff | AC16: Official reference tariff | AD16: Official reference tariff | AE16: Official reference tariff | AF16: Official reference tariff | AH16: Combined round-trip efficiency | AK16: 0.950625
A17: NPV over study period | B17: EGP | C17: =IF(C65=1,SUM(D78:D98),"Invalid") -> 98257.868 | D17: =IF(D65=1,SUM(H78:H98),"Invalid") -> -289842.6 | E17: =IF(E65=1,SUM(L78:L98),"Invalid") -> -125124.27 | W17: Load distribution mode | Y17: Constant load | Z17: Constant load | AA17: Constant load | AB17: Constant load | AC17: Constant load | AD17: Constant load | AE17: Constant load | AF17: Constant load | AH17: Daylight hours | AK17: 12
A18: Simple payback | B18: years | C18: =IF(C65=0,"Invalid",IF(MIN(P79:P98)=999,"Not reached",MIN(P79:P98))) -> 3.6330159 | D18: =IF(D65=0,"Invalid",IF(MIN(R79:R98)=999,"Not reached",MIN(R79:R98))) -> Not reached | E18: =IF(E65=0,"Invalid",IF(MIN(T79:T98)=999,"Not reached",MIN(T79:T98))) -> 8.7959743 | H18: Unused fields: battery for solar-only and PV for battery-only. Grid-cycle mode applies only to the battery-only column. | W18: Daytime energy share | X18: % | Y18: 0.5 | Z18: 0.5 | AA18: 0.5 | AB18: 0.5 | AC18: 0.5 | AD18: 0.5 | AE18: 0.5 | AF18: 0.5 | AH18: Day / night energy split | AK18: 50% / 50%; constant-load assumption, not measured
A19: Discounted payback | B19: years | C19: =IF(C65=0,"Invalid",IF(MIN(Q79:Q98)=999,"Not reached",MIN(Q79:Q98))) -> 4.7500873 | D19: =IF(D65=0,"Invalid",IF(MIN(S79:S98)=999,"Not reached",MIN(S79:S98))) -> Not reached | E19: =IF(E65=0,"Invalid",IF(MIN(U79:U98)=999,"Not reached",MIN(U79:U98))) -> Not reached | W19: Roof input mode | Y19: Unspecified | Z19: Unspecified | AA19: Specified | AB19: Specified | AC19: Specified | AD19: Specified | AE19: Specified | AF19: Specified | AH19: PV charging window (hours) | AK19: 6
A20: Full-charge backup energy | B20: kWh AC | C20: =C68 -> 0 | D20: =D68 -> 12.48 | E20: =E68 -> 12.48 | H20: Live checks | J20: Solar only | K20: Battery only | L20: Solar and battery | W20: Available roof area | X20: m2 | Y20: Unspecified | Z20: Unspecified | AA20: 10 | AB20: 25 | AC20: 50 | AD20: 10 | AE20: 50 | AF20: 10 | AH20: Grid charging window (hours) | AK20: 8
A21: Maximum backup power | B21: kW | C21: =C69 -> 0 | D21: =D69 -> 5 | E21: =E69 -> 8 | H21: Errors | J21: =COUNTIFS(C926:C980,"ERROR:*") -> 0 | K21: =COUNTIFS(G926:G980,"ERROR:*") -> 0 | L21: =COUNTIFS(K926:K980,"ERROR:*") -> 0 | W21: Critical-load basis | Y21: Manager estimate; not measured | Z21: Manager estimate; not measured | AA21: Manager estimate; not measured | AB21: Manager estimate; not measured | AC21: Manager estimate; not measured | AD21: Manager estimate; not measured | AE21: Manager estimate; not measured | AF21: Manager estimate; not measured | AH21: Installation area multiplier | AK21: 1.5
A22: Backup hours from full charge | B22: hours | C22: =IF(C65=0,"Invalid",IF(C69=0,"Not available",IF(Inputs!$C$20="Unknown","Load unknown",IF(Inputs!$C$21>C69,"Load exceeds power limit",C68/Inputs!$C$21)))) -> Not available | D22: =IF(D65=0,"Invalid",IF(D69=0,"Not available",IF(Inputs!$C$20="Unknown","Load unknown",IF(Inputs!$C$21>D69,"Load exceeds power limit",D68/Inputs!$C$21)))) -> Load unknown | E22: =IF(E65=0,"Invalid",IF(E69=0,"Not available",IF(Inputs!$C$20="Unknown","Load unknown",IF(Inputs!$C$21>E69,"Load exceeds power limit",E68/Inputs!$C$21)))) -> Load unknown | H22: Warnings | J22: =COUNTIFS(C926:C980,"WARNING:*") -> 1 | K22: =COUNTIFS(G926:G980,"WARNING:*") -> 1 | L22: =COUNTIFS(K926:K980,"WARNING:*") -> 2 | W22: Critical load used for backup check | X22: kW | Y22: 4 | Z22: 4 | AA22: 4 | AB22: 4 | AC22: 4 | AD22: 4 | AE22: 4 | AF22: 4 | AH22: Annual maintenance / initial investment | AK22: 0.01
A23: Reserved backup energy | B23: kWh AC | C23: =IF(C58=1,C67*'Assumptions and Catalog'!$C$12,0) -> 0 | D23: =IF(D58=1,D67*'Assumptions and Catalog'!$C$12,0) -> 12.48 | E23: =IF(E58=1,E67*'Assumptions and Catalog'!$C$12,0) -> 2.496 | H23: Details | J23: =HYPERLINK("#'Scenarios'!C924","Open checks") -> Open checks | K23: =HYPERLINK("#'Scenarios'!G924","Open checks") -> Open checks | L23: =HYPERLINK("#'Scenarios'!K924","Open checks") -> Open checks | W23: Panel model slot | Y23: PV550 | Z23: PV670 | AA23: PV670 | AB23: PV670 | AC23: PV670 | AD23: PV670 | AE23: PV670 | AF23: PV670 | AH23: Battery replacement year | AK23: 11
A24: System role | C24: =IF(C65=0,"Invalid",IF(C15>0,IF(C69>0,"Bill savings + backup capability","Bill savings"),IF(C69>0,"Backup capability, no bill savings","No bill savings demonstrated"))) -> Bill savings | D24: =IF(D65=0,"Invalid",IF(D15>0,IF(D69>0,"Bill savings + backup capability","Bill savings"),IF(D69>0,"Backup capability, no bill savings","No bill savings demonstrated"))) -> Backup capability, no bill savings | E24: =IF(E65=0,"Invalid",IF(E15>0,IF(E69>0,"Bill savings + backup capability","Bill savings"),IF(E69>0,"Backup capability, no bill savings","No bill savings demonstrated"))) -> Bill savings + backup capability | W24: Panel rated power | X24: Wp | Y24: 550 | Z24: 670 | AA24: 670 | AB24: 670 | AC24: 670 | AD24: 670 | AE24: 670 | AF24: 670 | AH24: Battery replacement cost fraction | AK24: 1
A25: Financial outcome | C25: =IF(C65=0,"Invalid",IF(C17>0,"Positive NPV under assumptions",IF(C17=0,"Discounted breakeven","Negative NPV under assumptions"))) -> Positive NPV under assumptions | D25: =IF(D65=0,"Invalid",IF(D17>0,"Positive NPV under assumptions",IF(D17=0,"Discounted breakeven","Negative NPV under assumptions"))) -> Negative NPV under assumptions | E25: =IF(E65=0,"Invalid",IF(E17>0,"Positive NPV under assumptions",IF(E17=0,"Discounted breakeven","Negative NPV under assumptions"))) -> Negative NPV under assumptions | W25: Panel quantity | X25: units | Y25: 46 | Z25: 0 | AA25: 3 | AB25: 7 | AC25: 15 | AD25: 3 | AE25: 15 | AF25: 3 | AH25: Inverter replacement year | AK25: 12
A26: Roof area status | C26: =IF(Inputs!$C$14="Unspecified","Roof fit not verified",IF(C59<=Inputs!$C$15,"Within available area","Exceeds available area")) -> Roof fit not verified | D26: =IF(Inputs!$C$14="Unspecified","Roof fit not verified",IF(D59<=Inputs!$C$15,"Within available area","Exceeds available area")) -> Roof fit not verified | E26: =IF(Inputs!$C$14="Unspecified","Roof fit not verified",IF(E59<=Inputs!$C$15,"Within available area","Exceeds available area")) -> Roof fit not verified | W26: Battery unit model / capacity | Y26: BAT10 / 10 kWh | Z26: BAT10 / 10 kWh | AA26: BAT10 / 10 kWh | AB26: BAT10 / 10 kWh | AC26: BAT10 / 10 kWh | AD26: BAT10 / 10 kWh | AE26: BAT10 / 10 kWh | AF26: BAT10 / 10 kWh | AH26: Inverter replacement cost fraction | AK26: 1
W27: Battery unit quantity | X27: units | Y27: 0 | Z27: 1 | AA27: 1 | AB27: 1 | AC27: 2 | AD27: 3 | AE27: 5 | AF27: 5 | AH27: Battery capacity degradation per year | AK27: 0.02
A28: Full-charge backup is not guaranteed at outage time. Motor surge, load phase balance and site checks are not modeled. | W28: Temporary inverter catalog slot | Y28: GRID10 (25 kW test) | Z28: HYB5 (3 kW test) | AA28: HYB5 (3 kW test) | AB28: HYB5 (5 kW test) | AC28: HYB5 (10 kW test) | AD28: HYB5 (5 kW test) | AE28: HYB5 (10 kW test) | AF28: HYB5 (5 kW test) | AH28: Battery auxiliary use (kWh/day) | AK28: 0
A29: NPV excludes financing, taxes and outage value. The no-investment baseline has NPV = 0. | W29: Inverter AC rating | X29: kW | Y29: 25 | Z29: 3 | AA29: 3 | AB29: 5 | AC29: 10 | AD29: 5 | AE29: 10 | AF29: 5 | AH29: Cairo yield (kWh/kWp/day) | AK29: 4.98
W30: Inverter PV limit (assumed 1.3 x AC) | X30: kWp | Y30: 32.5 | Z30: 3.9 | AA30: 3.9 | AB30: 6.5 | AC30: 13 | AD30: 6.5 | AE30: 13 | AF30: 6.5 | AH30: PV550 area (m2/panel) | AK30: 2.6
A31: Battery savings vs matched PV | B31: EGP/year | E31: =IF(E65=1,SUM(Q661:Q672)-SUM(N661:N672),"Invalid") -> 10701.835 | W31: Effective battery charge power | X31: kW | Y31: 0 | Z31: 3 | AA31: 3 | AB31: 5 | AC31: 10 | AD31: 5 | AE31: 10 | AF31: 5 | AH31: PV670 area (m2/panel) | AK31: 2.7
A32: Incremental battery investment | B32: EGP | E32: =E61*(1+'Assumptions and Catalog'!$C$17) -> 240064 | W32: Effective battery discharge power | X32: kW | Y32: 0 | Z32: 3 | AA32: 3 | AB32: 5 | AC32: 10 | AD32: 5 | AE32: 10 | AF32: 5 | AH32: Battery usable fraction | AK32: 0.8
A33: Incremental comparison uses the same PV and hybrid inverter without a battery; no cheaper inverter alternative is assumed. | W33: Reserved share of usable capacity | X33: % | Y33: 0.2 | Z33: 1 | AA33: 0.2 | AB33: 0.2 | AC33: 0.2 | AD33: 0.2 | AE33: 0.2 | AF33: 0.2 | AH33: BAT10 charge/discharge limit (kW/unit) | AK33: 5
W34: Battery-only operating mode | Y34: Backup | Z34: Backup | AA34: Backup | AB34: Backup | AC34: Backup | AD34: Backup | AE34: Backup | AF34: Backup | AH34: Battery compatibility group | AK34: LV; assumed, not manufacturer verified
A35: =HYPERLINK("#'Solar Production'!A19","Open monthly solar production and bill savings") -> Open monthly solar production and bill savings | W35: Grid-cycle delivery setting (inactive) | X35: kWh/day | Y35: 8 | Z35: 8 | AA35: 8 | AB35: 8 | AC35: 8 | AD35: 8 | AE35: 8 | AF35: 8 | AH35: Inverter PV limit assumption | AK35: 1.3 x AC rating; same ratio as existing catalog
A36: Experimental copy: monthly seasonality enabled. Battery dispatch is still a monthly approximation. | W36: Panel unit cost from source | X36: EGP | Y36: 4260.8696 | Z36: Not used | AA36: 5766.6667 | AB36: 4690 | AC36: 4690 | AD36: 10766.667 | AE36: 4690 | AF36: 5833.3333 | AH36: Inverter charge power assumption | AK36: Equal to AC rating, capped by battery power
W37: Battery unit cost from source | X37: EGP | Y37: 115000 | Z37: 115000 | AA37: 115000 | AB37: 115000 | AC37: 115000 | AD37: 115000 | AE37: 115000 | AF37: 115000 | AH37: Critical load | AK37: 4 kW from manager estimate; not measured
W38: Inverter cost from source | X38: EGP | Y38: 140000 | Z38: 30000 | AA38: 30000 | AB38: 50000 | AC38: 100000 | AD38: 50000 | AE38: 100000 | AF38: 50000 | AH38: Backup interpretation | AK38: Full charge is conditional, not guaranteed at outage time
W39: Declared source capital total | X39: EGP | Y39: 413500 | Z39: 172500 | AA39: 197300 | AB39: 247000 | AC39: 467500 | AD39: 454800 | AE39: 812850 | AF39: 662500 | AH39: Backup outage energy | AK39: Outage events and recharge losses are not scheduled
W40: BOS fraction reconciling source total | X40: % | Y40: 0.23065476 | Z40: 0.18965517 | AA40: 0.21565003 | AB40: 0.24854673 | AC40: 0.16772824 | AD40: 0.064357594 | AE40: 0.090561481 | AF40: 0.031128405 | AH40: Source cost basis | AK40: Declared scenario total retained. Component range midpoints used.
W41: Source installation midpoint | X41: EGP | Y41: 77500 | Z41: 27500 | AA41: 35000 | AB41: 50000 | AC41: 67500 | AD41: 27500 | AE41: 67500 | AF41: 20000 | AH41: BOS override | AK41: (Declared capital total - equipment cost) / equipment cost
...

Sheet Future Changes

Sheet Saved Scenarios

Sheet Solar Production
A2: AVESTA - Solar Production | Experimental Copy
A3: Cairo fixed location. Yellow cells are editable. Monthly battery dispatch remains an approximation.
A5: Panel tilt (degrees) | C5: 30 | E5: Tilt: 0 = horizontal; 90 = vertical.
A6: Compass azimuth (deg) | C6: 180 | E6: Azimuth: 0/360 = north; 90 = east; 180 = south; 270 = west.
A7: Study year shown | C7: 1 | E7: The same roof orientation applies to both solar configurations.
A8: Calendar year shown | C8: ='Assumptions and Catalog'!C24+C7-1 -> 2027
A9: Latitude (fixed) | C9: 30.0444 | E9: PVGIS 5.3 / SARAH3 | Climate: 2005-2023 | Retrieved: 26 Oct 2026
A10: Longitude (fixed) | C10: 31.2357 | E10: Crystalline silicon; free-standing; terrain horizon included.
A11: PVGIS system loss | C11: 0.14 | E11: 14% system loss is already included; no second performance ratio.
A12: Solar input status | C12: =IF(AND(ISNUMBER(C5),C5>=0,C5<=90,ISNUMBER(C6),C6>=0,C6<=360,ISNUMBER(C7),C7>=1,C7<='Assumptions and Catalog'!C6,C7<=20,C7=INT(C7)),"OK","INVALID: tilt 0-90, azimuth 0-360, study year within horizon (max 20)") -> OK
A14: =HYPERLINK("https://re.jrc.ec.europa.eu/api/v5_3/PVcalc?lat=30.0444&lon=31.2357&peakpower=1&loss=14&raddatabase=PVGIS-SARAH3&pvtechchoice=crystSi&mountingplace=free&angle="&C5&"&aspect="&(C6-180)&"&outputformat=json","Open PVGIS source for selected tilt and azimuth (internet required)") -> Open PVGIS source for selected tilt and azimuth (internet required)
A15: =HYPERLINK("https://joint-research-centre.ec.europa.eu/photovoltaic-geographical-information-system-pvgis/using-pvgis-5/pvgis-5-user-manual_en","PVGIS methodology and data documentation") -> PVGIS methodology and data documentation
A16: Offline calculation: bilinear interpolation of PVGIS results on a 5-degree tilt / 15-degree azimuth grid.
A17: Source values are for 1 kWp. Monthly climate averages are not a forecast of the selected calendar year.
A19: Month | B19: Ref. days | C19: PV yield kWh/kWp/mo | D19: PV yield kWh/kWp/day | E19: Solar only PV kWh | F19: Solar only Bill saving EGP | G19: Combined PV kWh | H19: Combined Bill saving EGP | I19: Battery only Bill saving EGP | J19: Calendar days
A20: 1 | B20: 31 | C20: =IF($C$12="OK",(1-$C$44)*(1-$C$45)*INDEX($D$70:$D$5769,($C$40/5*25+$C$42/15)*12+A20)+$C$44*(1-$C$45)*INDEX($D$70:$D$5769,($C$41/5*25+$C$42/15)*12+A20)+(1-$C$44)*$C$45*INDEX($D$70:$D$5769,($C$40/5*25+$C$43/15)*12+A20)+$C$44*$C$45*INDEX($D$70:$D$5769,($C$41/5*25+$C$43/15)*12+A20),NA()) -> 131.3 | D20: =C20/B20 -> 4.2354839 | E20: =IF(AND($C$12="OK",Scenarios!C$65=1),SUMIFS(Scenarios!$F$161:$F$400,Scenarios!$A$161:$A$400,$C$7,Scenarios!$B$161:$B$400,A20),NA()) -> 1155.44 | F20: =IF(AND($C$12="OK",Scenarios!C$65=1),SUMIFS(Scenarios!$O$161:$O$400,Scenarios!$A$161:$A$400,$C$7,Scenarios!$B$161:$B$400,A20),NA()) -> 3258.3408 | G20: =IF(AND($C$12="OK",Scenarios!E$65=1),SUMIFS(Scenarios!$F$661:$F$900,Scenarios!$A$661:$A$900,$C$7,Scenarios!$B$661:$B$900,A20),NA()) -> 1444.3 | H20: =IF(AND($C$12="OK",Scenarios!E$65=1),SUMIFS(Scenarios!$O$661:$O$900,Scenarios!$A$661:$A$900,$C$7,Scenarios!$B$661:$B$900,A20),NA()) -> 4045.9905 | I20: =IF(AND($C$12="OK",Scenarios!D$65=1),SUMIFS(Scenarios!$O$411:$O$650,Scenarios!$A$411:$A$650,$C$7,Scenarios!$B$411:$B$650,A20),NA()) -> 0 | J20: =DAY(DATE($C$8,A20+1,0)) -> 31
A21: 2 | B21: 28 | C21: =IF($C$12="OK",(1-$C$44)*(1-$C$45)*INDEX($D$70:$D$5769,($C$40/5*25+$C$42/15)*12+A21)+$C$44*(1-$C$45)*INDEX($D$70:$D$5769,($C$41/5*25+$C$42/15)*12+A21)+(1-$C$44)*$C$45*INDEX($D$70:$D$5769,($C$40/5*25+$C$43/15)*12+A21)+$C$44*$C$45*INDEX($D$70:$D$5769,($C$41/5*25+$C$43/15)*12+A21),NA()) -> 129.45 | D21: =C21/B21 -> 4.6232143 | E21: =IF(AND($C$12="OK",Scenarios!C$65=1),SUMIFS(Scenarios!$F$161:$F$400,Scenarios!$A$161:$A$400,$C$7,Scenarios!$B$161:$B$400,A21),NA()) -> 1139.16 | F21: =IF(AND($C$12="OK",Scenarios!C$65=1),SUMIFS(Scenarios!$O$161:$O$400,Scenarios!$A$161:$A$400,$C$7,Scenarios!$B$161:$B$400,A21),NA()) -> 3186.036 | G21: =IF(AND($C$12="OK",Scenarios!E$65=1),SUMIFS(Scenarios!$F$661:$F$900,Scenarios!$A$661:$A$900,$C$7,Scenarios!$B$661:$B$900,A21),NA()) -> 1423.95 | H21: =IF(AND($C$12="OK",Scenarios!E$65=1),SUMIFS(Scenarios!$O$661:$O$900,Scenarios!$A$661:$A$900,$C$7,Scenarios!$B$661:$B$900,A21),NA()) -> 4091.885 | I21: =IF(AND($C$12="OK",Scenarios!D$65=1),SUMIFS(Scenarios!$O$411:$O$650,Scenarios!$A$411:$A$650,$C$7,Scenarios!$B$411:$B$650,A21),NA()) -> 0 | J21: =DAY(DATE($C$8,A21+1,0)) -> 28
A22: 3 | B22: 31 | C22: =IF($C$12="OK",(1-$C$44)*(1-$C$45)*INDEX($D$70:$D$5769,($C$40/5*25+$C$42/15)*12+A22)+$C$44*(1-$C$45)*INDEX($D$70:$D$5769,($C$41/5*25+$C$42/15)*12+A22)+(1-$C$44)*$C$45*INDEX($D$70:$D$5769,($C$40/5*25+$C$43/15)*12+A22)+$C$44*$C$45*INDEX($D$70:$D$5769,($C$41/5*25+$C$43/15)*12+A22),NA()) -> 161.06 | D22: =C22/B22 -> 5.1954839 | E22: =IF(AND($C$12="OK",Scenarios!C$65=1),SUMIFS(Scenarios!$F$161:$F$400,Scenarios!$A$161:$A$400,$C$7,Scenarios!$B$161:$B$400,A22),NA()) -> 1417.328 | F22: =IF(AND($C$12="OK",Scenarios!C$65=1),SUMIFS(Scenarios!$O$161:$O$400,Scenarios!$A$161:$A$400,$C$7,Scenarios!$B$161:$B$400,A22),NA()) -> 3527.397 | G22: =IF(AND($C$12="OK",Scenarios!E$65=1),SUMIFS(Scenarios!$F$661:$F$900,Scenarios!$A$661:$A$900,$C$7,Scenarios!$B$661:$B$900,A22),NA()) -> 1771.66 | H22: =IF(AND($C$12="OK",Scenarios!E$65=1),SUMIFS(Scenarios!$O$661:$O$900,Scenarios!$A$661:$A$900,$C$7,Scenarios!$B$661:$B$900,A22),NA()) -> 4522.2656 | I22: =IF(AND($C$12="OK",Scenarios!D$65=1),SUMIFS(Scenarios!$O$411:$O$650,Scenarios!$A$411:$A$650,$C$7,Scenarios!$B$411:$B$650,A22),NA()) -> 0 | J22: =DAY(DATE($C$8,A22+1,0)) -> 31
A23: 4 | B23: 30 | C23: =IF($C$12="OK",(1-$C$44)*(1-$C$45)*INDEX($D$70:$D$5769,($C$40/5*25+$C$42/15)*12+A23)+$C$44*(1-$C$45)*INDEX($D$70:$D$5769,($C$41/5*25+$C$42/15)*12+A23)+(1-$C$44)*$C$45*INDEX($D$70:$D$5769,($C$40/5*25+$C$43/15)*12+A23)+$C$44*$C$45*INDEX($D$70:$D$5769,($C$41/5*25+$C$43/15)*12+A23),NA()) -> 160.86 | D23: =C23/B23 -> 5.362 | E23: =IF(AND($C$12="OK",Scenarios!C$65=1),SUMIFS(Scenarios!$F$161:$F$400,Scenarios!$A$161:$A$400,$C$7,Scenarios!$B$161:$B$400,A23),NA()) -> 1415.568 | F23: =IF(AND($C$12="OK",Scenarios!C$65=1),SUMIFS(Scenarios!$O$161:$O$400,Scenarios!$A$161:$A$400,$C$7,Scenarios!$B$161:$B$400,A23),NA()) -> 3413.61 | G23: =IF(AND($C$12="OK",Scenarios!E$65=1),SUMIFS(Scenarios!$F$661:$F$900,Scenarios!$A$661:$A$900,$C$7,Scenarios!$B$661:$B$900,A23),NA()) -> 1769.46 | H23: =IF(AND($C$12="OK",Scenarios!E$65=1),SUMIFS(Scenarios!$O$661:$O$900,Scenarios!$A$661:$A$900,$C$7,Scenarios!$B$661:$B$900,A23),NA()) -> 4378.8054 | I23: =IF(AND($C$12="OK",Scenarios!D$65=1),SUMIFS(Scenarios!$O$411:$O$650,Scenarios!$A$411:$A$650,$C$7,Scenarios!$B$411:$B$650,A23),NA()) -> 0 | J23: =DAY(DATE($C$8,A23+1,0)) -> 30
A24: 5 | B24: 31 | C24: =IF($C$12="OK",(1-$C$44)*(1-$C$45)*INDEX($D$70:$D$5769,($C$40/5*25+$C$42/15)*12+A24)+$C$44*(1-$C$45)*INDEX($D$70:$D$5769,($C$41/5*25+$C$42/15)*12+A24)+(1-$C$44)*$C$45*INDEX($D$70:$D$5769,($C$40/5*25+$C$43/15)*12+A24)+$C$44*$C$45*INDEX($D$70:$D$5769,($C$41/5*25+$C$43/15)*12+A24),NA()) -> 162.72 | D24: =C24/B24 -> 5.2490323 | E24: =IF(AND($C$12="OK",Scenarios!C$65=1),SUMIFS(Scenarios!$F$161:$F$400,Scenarios!$A$161:$A$400,$C$7,Scenarios!$B$161:$B$400,A24),NA()) -> 1431.936 | F24: =IF(AND($C$12="OK",Scenarios!C$65=1),SUMIFS(Scenarios!$O$161:$O$400,Scenarios!$A$161:$A$400,$C$7,Scenarios!$B$161:$B$400,A24),NA()) -> 3527.397 | G24: =IF(AND($C$12="OK",Scenarios!E$65=1),SUMIFS(Scenarios!$F$661:$F$900,Scenarios!$A$661:$A$900,$C$7,Scenarios!$B$661:$B$900,A24),NA()) -> 1789.92 | H24: =IF(AND($C$12="OK",Scenarios!E$65=1),SUMIFS(Scenarios!$O$661:$O$900,Scenarios!$A$661:$A$900,$C$7,Scenarios!$B$661:$B$900,A24),NA()) -> 4522.2656 | I24: =IF(AND($C$12="OK",Scenarios!D$65=1),SUMIFS(Scenarios!$O$411:$O$650,Scenarios!$A$411:$A$650,$C$7,Scenarios!$B$411:$B$650,A24),NA()) -> 0 | J24: =DAY(DATE($C$8,A24+1,0)) -> 31
A25: 6 | B25: 30 | C25: =IF($C$12="OK",(1-$C$44)*(1-$C$45)*INDEX($D$70:$D$5769,($C$40/5*25+$C$42/15)*12+A25)+$C$44*(1-$C$45)*INDEX($D$70:$D$5769,($C$41/5*25+$C$42/15)*12+A25)+(1-$C$44)*$C$45*INDEX($D$70:$D$5769,($C$40/5*25+$C$43/15)*12+A25)+$C$44*$C$45*INDEX($D$70:$D$5769,($C$41/5*25+$C$43/15)*12+A25),NA()) -> 158.62 | D25: =C25/B25 -> 5.2873333 | E25: =IF(AND($C$12="OK",Scenarios!C$65=1),SUMIFS(Scenarios!$F$161:$F$400,Scenarios!$A$161:$A$400,$C$7,Scenarios!$B$161:$B$400,A25),NA()) -> 1395.856 | F25: =IF(AND($C$12="OK",Scenarios!C$65=1),SUMIFS(Scenarios!$O$161:$O$400,Scenarios!$A$161:$A$400,$C$7,Scenarios!$B$161:$B$400,A25),NA()) -> 3413.61 | G25: =IF(AND($C$12="OK",Scenarios!E$65=1),SUMIFS(Scenarios!$F$661:$F$900,Scenarios!$A$661:$A$900,$C$7,Scenarios!$B$661:$B$900,A25),NA()) -> 1744.82 | H25: =IF(AND($C$12="OK",Scenarios!E$65=1),SUMIFS(Scenarios!$O$661:$O$900,Scenarios!$A$661:$A$900,$C$7,Scenarios!$B$661:$B$900,A25),NA()) -> 4378.8054 | I25: =IF(AND($C$12="OK",Scenarios!D$65=1),SUMIFS(Scenarios!$O$411:$O$650,Scenarios!$A$411:$A$650,$C$7,Scenarios!$B$411:$B$650,A25),NA()) -> 0 | J25: =DAY(DATE($C$8,A25+1,0)) -> 30
A26: 7 | B26: 31 | C26: =IF($C$12="OK",(1-$C$44)*(1-$C$45)*INDEX($D$70:$D$5769,($C$40/5*25+$C$42/15)*12+A26)+$C$44*(1-$C$45)*INDEX($D$70:$D$5769,($C$41/5*25+$C$42/15)*12+A26)+(1-$C$44)*$C$45*INDEX($D$70:$D$5769,($C$40/5*25+$C$43/15)*12+A26)+$C$44*$C$45*INDEX($D$70:$D$5769,($C$41/5*25+$C$43/15)*12+A26),NA()) -> 164.66 | D26: =C26/B26 -> 5.3116129 | E26: =IF(AND($C$12="OK",Scenarios!C$65=1),SUMIFS(Scenarios!$F$161:$F$400,Scenarios!$A$161:$A$400,$C$7,Scenarios!$B$161:$B$400,A26),NA()) -> 1449.008 | F26: =IF(AND($C$12="OK",Scenarios!C$65=1),SUMIFS(Scenarios!$O$161:$O$400,Scenarios!$A$161:$A$400,$C$7,Scenarios!$B$161:$B$400,A26),NA()) -> 3527.397 | G26: =IF(AND($C$12="OK",Scenarios!E$65=1),SUMIFS(Scenarios!$F$661:$F$900,Scenarios!$A$661:$A$900,$C$7,Scenarios!$B$661:$B$900,A26),NA()) -> 1811.26 | H26: =IF(AND($C$12="OK",Scenarios!E$65=1),SUMIFS(Scenarios!$O$661:$O$900,Scenarios!$A$661:$A$900,$C$7,Scenarios!$B$661:$B$900,A26),NA()) -> 4522.2656 | I26: =IF(AND($C$12="OK",Scenarios!D$65=1),SUMIFS(Scenarios!$O$411:$O$650,Scenarios!$A$411:$A$650,$C$7,Scenarios!$B$411:$B$650,A26),NA()) -> 0 | J26: =DAY(DATE($C$8,A26+1,0)) -> 31
A27: 8 | B27: 31 | C27: =IF($C$12="OK",(1-$C$44)*(1-$C$45)*INDEX($D$70:$D$5769,($C$40/5*25+$C$42/15)*12+A27)+$C$44*(1-$C$45)*INDEX($D$70:$D$5769,($C$41/5*25+$C$42/15)*12+A27)+(1-$C$44)*$C$45*INDEX($D$70:$D$5769,($C$40/5*25+$C$43/15)*12+A27)+$C$44*$C$45*INDEX($D$70:$D$5769,($C$41/5*25+$C$43/15)*12+A27),NA()) -> 166.8 | D27: =C27/B27 -> 5.3806452 | E27: =IF(AND($C$12="OK",Scenarios!C$65=1),SUMIFS(Scenarios!$F$161:$F$400,Scenarios!$A$161:$A$400,$C$7,Scenarios!$B$161:$B$400,A27),NA()) -> 1467.84 | F27: =IF(AND($C$12="OK",Scenarios!C$65=1),SUMIFS(Scenarios!$O$161:$O$400,Scenarios!$A$161:$A$400,$C$7,Scenarios!$B$161:$B$400,A27),NA()) -> 3527.397 | G27: =IF(AND($C$12="OK",Scenarios!E$65=1),SUMIFS(Scenarios!$F$661:$F$900,Scenarios!$A$661:$A$900,$C$7,Scenarios!$B$661:$B$900,A27),NA()) -> 1834.8 | H27: =IF(AND($C$12="OK",Scenarios!E$65=1),SUMIFS(Scenarios!$O$661:$O$900,Scenarios!$A$661:$A$900,$C$7,Scenarios!$B$661:$B$900,A27),NA()) -> 4522.2656 | I27: =IF(AND($C$12="OK",Scenarios!D$65=1),SUMIFS(Scenarios!$O$411:$O$650,Scenarios!$A$411:$A$650,$C$7,Scenarios!$B$411:$B$650,A27),NA()) -> 0 | J27: =DAY(DATE($C$8,A27+1,0)) -> 31
A28: 9 | B28: 30 | C28: =IF($C$12="OK",(1-$C$44)*(1-$C$45)*INDEX($D$70:$D$5769,($C$40/5*25+$C$42/15)*12+A28)+$C$44*(1-$C$45)*INDEX($D$70:$D$5769,($C$41/5*25+$C$42/15)*12+A28)+(1-$C$44)*$C$45*INDEX($D$70:$D$5769,($C$40/5*25+$C$43/15)*12+A28)+$C$44*$C$45*INDEX($D$70:$D$5769,($C$41/5*25+$C$43/15)*12+A28),NA()) -> 161 | D28: =C28/B28 -> 5.3666667 | E28: =IF(AND($C$12="OK",Scenarios!C$65=1),SUMIFS(Scenarios!$F$161:$F$400,Scenarios!$A$161:$A$400,$C$7,Scenarios!$B$161:$B$400,A28),NA()) -> 1416.8 | F28: =IF(AND($C$12="OK",Scenarios!C$65=1),SUMIFS(Scenarios!$O$161:$O$400,Scenarios!$A$161:$A$400,$C$7,Scenarios!$B$161:$B$400,A28),NA()) -> 3413.61 | G28: =IF(AND($C$12="OK",Scenarios!E$65=1),SUMIFS(Scenarios!$F$661:$F$900,Scenarios!$A$661:$A$900,$C$7,Scenarios!$B$661:$B$900,A28),NA()) -> 1771 | H28: =IF(AND($C$12="OK",Scenarios!E$65=1),SUMIFS(Scenarios!$O$661:$O$900,Scenarios!$A$661:$A$900,$C$7,Scenarios!$B$661:$B$900,A28),NA()) -> 4378.8054 | I28: =IF(AND($C$12="OK",Scenarios!D$65=1),SUMIFS(Scenarios!$O$411:$O$650,Scenarios!$A$411:$A$650,$C$7,Scenarios!$B$411:$B$650,A28),NA()) -> 0 | J28: =DAY(DATE($C$8,A28+1,0)) -> 30
A29: 10 | B29: 31 | C29: =IF($C$12="OK",(1-$C$44)*(1-$C$45)*INDEX($D$70:$D$5769,($C$40/5*25+$C$42/15)*12+A29)+$C$44*(1-$C$45)*INDEX($D$70:$D$5769,($C$41/5*25+$C$42/15)*12+A29)+(1-$C$44)*$C$45*INDEX($D$70:$D$5769,($C$40/5*25+$C$43/15)*12+A29)+$C$44*$C$45*INDEX($D$70:$D$5769,($C$41/5*25+$C$43/15)*12+A29),NA()) -> 154.53 | D29: =C29/B29 -> 4.9848387 | E29: =IF(AND($C$12="OK",Scenarios!C$65=1),SUMIFS(Scenarios!$F$161:$F$400,Scenarios!$A$161:$A$400,$C$7,Scenarios!$B$161:$B$400,A29),NA()) -> 1359.864 | F29: =IF(AND($C$12="OK",Scenarios!C$65=1),SUMIFS(Scenarios!$O$161:$O$400,Scenarios!$A$161:$A$400,$C$7,Scenarios!$B$161:$B$400,A29),NA()) -> 3527.397 | G29: =IF(AND($C$12="OK",Scenarios!E$65=1),SUMIFS(Scenarios!$F$661:$F$900,Scenarios!$A$661:$A$900,$C$7,Scenarios!$B$661:$B$900,A29),NA()) -> 1699.83 | H29: =IF(AND($C$12="OK",Scenarios!E$65=1),SUMIFS(Scenarios!$O$661:$O$900,Scenarios!$A$661:$A$900,$C$7,Scenarios!$B$661:$B$900,A29),NA()) -> 4522.2656 | I29: =IF(AND($C$12="OK",Scenarios!D$65=1),SUMIFS(Scenarios!$O$411:$O$650,Scenarios!$A$411:$A$650,$C$7,Scenarios!$B$411:$B$650,A29),NA()) -> 0 | J29: =DAY(DATE($C$8,A29+1,0)) -> 31
A30: 11 | B30: 30 | C30: =IF($C$12="OK",(1-$C$44)*(1-$C$45)*INDEX($D$70:$D$5769,($C$40/5*25+$C$42/15)*12+A30)+$C$44*(1-$C$45)*INDEX($D$70:$D$5769,($C$41/5*25+$C$42/15)*12+A30)+(1-$C$44)*$C$45*INDEX($D$70:$D$5769,($C$40/5*25+$C$43/15)*12+A30)+$C$44*$C$45*INDEX($D$70:$D$5769,($C$41/5*25+$C$43/15)*12+A30),NA()) -> 136.97 | D30: =C30/B30 -> 4.5656667 | E30: =IF(AND($C$12="OK",Scenarios!C$65=1),SUMIFS(Scenarios!$F$161:$F$400,Scenarios!$A$161:$A$400,$C$7,Scenarios!$B$161:$B$400,A30),NA()) -> 1205.336 | F30: =IF(AND($C$12="OK",Scenarios!C$65=1),SUMIFS(Scenarios!$O$161:$O$400,Scenarios!$A$161:$A$400,$C$7,Scenarios!$B$161:$B$400,A30),NA()) -> 3399.0475 | G30: =IF(AND($C$12="OK",Scenarios!E$65=1),SUMIFS(Scenarios!$F$661:$F$900,Scenarios!$A$661:$A$900,$C$7,Scenarios!$B$661:$B$900,A30),NA()) -> 1506.67 | H30: =IF(AND($C$12="OK",Scenarios!E$65=1),SUMIFS(Scenarios!$O$661:$O$900,Scenarios!$A$661:$A$900,$C$7,Scenarios!$B$661:$B$900,A30),NA()) -> 4329.0191 | I30: =IF(AND($C$12="OK",Scenarios!D$65=1),SUMIFS(Scenarios!$O$411:$O$650,Scenarios!$A$411:$A$650,$C$7,Scenarios!$B$411:$B$650,A30),NA()) -> 0 | J30: =DAY(DATE($C$8,A30+1,0)) -> 30
A31: 12 | B31: 31 | C31: =IF($C$12="OK",(1-$C$44)*(1-$C$45)*INDEX($D$70:$D$5769,($C$40/5*25+$C$42/15)*12+A31)+$C$44*(1-$C$45)*INDEX($D$70:$D$5769,($C$41/5*25+$C$42/15)*12+A31)+(1-$C$44)*$C$45*INDEX($D$70:$D$5769,($C$40/5*25+$C$43/15)*12+A31)+$C$44*$C$45*INDEX($D$70:$D$5769,($C$41/5*25+$C$43/15)*12+A31),NA()) -> 130.4 | D31: =C31/B31 -> 4.2064516 | E31: =IF(AND($C$12="OK",Scenarios!C$65=1),SUMIFS(Scenarios!$F$161:$F$400,Scenarios!$A$161:$A$400,$C$7,Scenarios!$B$161:$B$400,A31),NA()) -> 1147.52 | F31: =IF(AND($C$12="OK",Scenarios!C$65=1),SUMIFS(Scenarios!$O$161:$O$400,Scenarios!$A$161:$A$400,$C$7,Scenarios!$B$161:$B$400,A31),NA()) -> 3236.0064 | G31: =IF(AND($C$12="OK",Scenarios!E$65=1),SUMIFS(Scenarios!$F$661:$F$900,Scenarios!$A$661:$A$900,$C$7,Scenarios!$B$661:$B$900,A31),NA()) -> 1434.4 | H31: =IF(AND($C$12="OK",Scenarios!E$65=1),SUMIFS(Scenarios!$O$661:$O$900,Scenarios!$A$661:$A$900,$C$7,Scenarios!$B$661:$B$900,A31),NA()) -> 4019.451 | I31: =IF(AND($C$12="OK",Scenarios!D$65=1),SUMIFS(Scenarios!$O$411:$O$650,Scenarios!$A$411:$A$650,$C$7,Scenarios!$B$411:$B$650,A31),NA()) -> 0 | J31: =DAY(DATE($C$8,A31+1,0)) -> 31
A32: Annual total | B32: =SUM(B20:B31) -> 365 | C32: =SUM(C20:C31) -> 1818.37 | D32: =C32/B32 -> 4.9818356 | E32: =SUM(E20:E31) -> 16001.656 | F32: =SUM(F20:F31) -> 40957.246 | G32: =SUM(G20:G31) -> 20002.07 | H32: =SUM(H20:H31) -> 52234.09 | I32: =SUM(I20:I31) -> 0 | J32: =SUM(J20:J31) -> 365
A34: Bill savings = baseline bill minus new bill. Unused PV has no export revenue.
A35: Net savings below include annual maintenance and replacement costs from the existing financial model.
A36: Annual net saving EGP | E36: =IF(AND($C$12="OK",Scenarios!C65=1),INDEX(Scenarios!C79:C98,$C$7),NA()) -> 39522.846 | G36: =IF(AND($C$12="OK",Scenarios!E65=1),INDEX(Scenarios!K79:K98,$C$7),NA()) -> 48073.45 | I36: =IF(AND($C$12="OK",Scenarios!D65=1),INDEX(Scenarios!G79:G98,$C$7),NA()) -> -2730.64
A38: Interpolation calculations
A40: Lower tilt | C40: =MIN(85,INT(C5/5)*5) -> 30
A41: Upper tilt | C41: =C40+5 -> 35
A42: Lower azimuth | C42: =MIN(345,INT(C6/15)*15) -> 180
A43: Upper azimuth | C43: =C42+15 -> 195
A44: Tilt weight | C44: =(C5-C40)/5 -> 0
A45: Azimuth weight | C45: =(C6-C42)/15 -> 0
A47: Model limits and next step
A48: Next: evaluate battery benefit with hourly PV, load and state-of-charge calculations, not monthly budgets.
...
