Workbook

Sheet Inputs
A2: AVESTA — Case Inputs | J2: Selected consumption and bill
A3: Edit the yellow cells. Location is fixed at Cairo. Initial values are the previous El Mo3alem example, not new measurements. | J3: Input status | L3: =IF(OR(C10<=0,COUNT(C10)=0),"Enter billing days",IF(AND(C6<>"Bill only",OR(C7<0,COUNT(C7)=0)),"Enter consumption",IF(AND(C6<>"Consumption only",OR(C8<0,COUNT(C8)=0)),"Enter bill amount",IF(AND(C6="Bill only",C66<>1),"Bill does not give a unique consumption",IF(AND(C14="Specified",OR(C15<=0,COUNT(C15)=0)),"Enter a positive area",IF(AND(C17="Known",OR(C18<0,C18>1,COUNT(C18)=0)),"Check daytime share",IF(AND(C20="Known",OR(C21<=0,COUNT(C21)=0)),"Enter a positive critical load","Ready for indicative calculation"))))))) -> Ready for indicative calculation
J4: Selected monthly use (kWh) | L4: =IF(L3<>"Ready for indicative calculation","Not available",IF(C6="Bill only",SUM(G50:G63),C7)) -> 2421
A5: Case name | C5: El Mo3alem shop — example | J5: Average consumption (kWh/day) | L5: =IF(ISNUMBER(L4),L4/C10,"Not available") -> 80.7
A6: Input mode | C6: Bill and consumption | J6: Active daytime energy share | L6: =IF(C17="Known",C18,'Assumptions and Catalog'!$C$13/24) -> 0.5
A7: Monthly consumption (kWh) | C7: 2421 | E7: Monthly use, not the cumulative meter reading | J7: Reference official bill (EGP) | L7: =IF(ISNUMBER(L4),IF(Inputs!$C$9="Residential",IF(L4<='Assumptions and Catalog'!$C$50,L4*'Assumptions and Catalog'!$H$50+'Assumptions and Catalog'!$E$50+'Assumptions and Catalog'!$F$50,IF(L4<='Assumptions and Catalog'!$C$51,L4*'Assumptions and Catalog'!$H$51+'Assumptions and Catalog'!$E$51+'Assumptions and Catalog'!$F$51,IF(L4<='Assumptions and Catalog'!$C$52,L4*'Assumptions and Catalog'!$H$52+'Assumptions and Catalog'!$E$52+'Assumptions and Catalog'!$F$52,IF(L4<='Assumptions and Catalog'!$C$53,L4*'Assumptions and Catalog'!$H$53+'Assumptions and Catalog'!$E$53+'Assumptions and Catalog'!$F$53,IF(L4<='Assumptions and Catalog'!$C$54,L4*'Assumptions and Catalog'!$H$54+'Assumptions and Catalog'!$E$54+'Assumptions and Catalog'!$F$54,IF(L4<='Assumptions and Catalog'!$C$55,L4*'Assumptions and Catalog'!$H$55+'Assumptions and Catalog'!$E$55+'Assumptions and Catalog'!$F$55,IF(L4<='Assumptions and Catalog'!$C$56,L4*'Assumptions and Catalog'!$H$56+'Assumptions and Catalog'!$E$56+'Assumptions and Catalog'!$F$56,IF(L4<='Assumptions and Catalog'!$C$57,L4*'Assumptions and Catalog'!$H$57+'Assumptions and Catalog'!$E$57+'Assumptions and Catalog'!$F$57,"Out of range")))))))),IF(L4<='Assumptions and Catalog'!$C$60,L4*'Assumptions and Catalog'!$H$60+'Assumptions and Catalog'!$E$60+'Assumptions and Catalog'!$F$60,IF(L4<='Assumptions and Catalog'!$C$61,L4*'Assumptions and Catalog'!$H$61+'Assumptions and Catalog'!$E$61+'Assumptions and Catalog'!$F$61,IF(L4<='Assumptions and Catalog'!$C$62,L4*'Assumptions and Catalog'!$H$62+'Assumptions and Catalog'!$E$62+'Assumptions and Catalog'!$F$62,IF(L4<='Assumptions and Catalog'!$C$63,L4*'Assumptions and Catalog'!$H$63+'Assumptions and Catalog'!$E$63+'Assumptions and Catalog'!$F$63,IF(L4<='Assumptions and Catalog'!$C$64,L4*'Assumptions and Catalog'!$H$64+'Assumptions and Catalog'!$E$64+'Assumptions and Catalog'!$F$64,IF(L4<='Assumptions and Catalog'!$C$65,L4*'Assumptions and Catalog'!$H$65+'Assumptions and Catalog'!$E$65+'Assumptions and Catalog'!$F$65,"Out of range"))))))),"Not available") -> 6867.22
A8: Monthly bill amount (EGP) | C8: 8279 | E8: Consumption bill, not a prepaid top-up | J8: Paid less official bill (EGP) | L8: =IF(AND(C6="Bill and consumption",ISNUMBER(L7)),C8-L7,"Not available") -> 1411.78
A9: Tariff category | C9: Commercial | J9: Active pricing basis | L9: =IF(AND(C6="Bill and consumption",C7>0,C11="Actual flat rate"),"Actual flat rate","Official") -> Actual flat rate
A10: Billing period days | C10: 30 | J10: Actual average (EGP/kWh) | L10: =IF(AND(C6="Bill and consumption",C7>0),C8/C7,"Not available") -> 3.4196613
A11: Pricing basis | C11: Actual flat rate | E11: Actual flat rate is available only with both bill amount and consumption | J11: Official average (EGP/kWh) | L11: =IF(AND(ISNUMBER(L4),L4>0),L7/L4,"Not available") -> 2.8365221
J12: Average rate difference (EGP/kWh) | L12: =IF(AND(ISNUMBER(L10),ISNUMBER(L11)),L10-L11,"Not available") -> 0.5831392
J13: Selected baseline bill (EGP) | L13: =IF(ISNUMBER(L4),IF(L9="Actual flat rate",L4*L10,L7),"Not available") -> 8279
A14: Available installation area | C14: Unspecified | J14: Reference-data status | L14: ="Reference tariffs and prices: verify before commercial use" -> Reference tariffs and prices: verify before commercial use
A15: Available area (m2) | C15: 50 | E15: Usable installation area after obstacles; unspecified area sets no cap
A17: Energy distribution | C17: Constant load
A18: Daytime energy share | C18: 0.5 | E18: Share of energy, not appliance count; night share is calculated
A20: Critical load | C20: Unknown
A21: Critical load (kW) | C21: 4 | E21: When unknown, no customer-specific backup hours are calculated
A39: Enter the case inputs, review assumptions, then choose equipment and quantities on the Scenarios sheet.
A40: Actual flat rate spreads the paid bill over kWh; it may differ from the marginal cost of avoided electricity.
A41: One representative day/night cycle per month with constant daily load. This is not an hourly simulation.
A47: Inverse-bill calculations — audit detail
A49: Tariff | B49: Above | C49: Up to | D49: Candidate kWh | E49: Candidate bill | F49: Valid solution 1/0 | G49: Accepted kWh
A50: ='Assumptions and Catalog'!$A$50 -> Residential | B50: ='Assumptions and Catalog'!$B$50 -> -1 | C50: ='Assumptions and Catalog'!$C$50 -> 0 | D50: =IF('Assumptions and Catalog'!$H$50=0,0,($C$8-'Assumptions and Catalog'!$E$50-'Assumptions and Catalog'!$F$50)/'Assumptions and Catalog'!$H$50) -> 0 | E50: =D50*'Assumptions and Catalog'!$H$50+'Assumptions and Catalog'!$E$50+'Assumptions and Catalog'!$F$50 -> 9 | F50: =IF(AND(A50=$C$9,D50>B50,D50<=C50,D50>=0,ABS(E50-$C$8)<='Assumptions and Catalog'!$C$25),1,0) -> 0 | G50: =IF(F50=1,D50,0) -> 0
A51: ='Assumptions and Catalog'!$A$51 -> Residential | B51: ='Assumptions and Catalog'!$B$51 -> 0 | C51: ='Assumptions and Catalog'!$C$51 -> 50 | D51: =IF('Assumptions and Catalog'!$H$51=0,0,($C$8-'Assumptions and Catalog'!$E$51-'Assumptions and Catalog'!$F$51)/'Assumptions and Catalog'!$H$51) -> 12173.529 | E51: =D51*'Assumptions and Catalog'!$H$51+'Assumptions and Catalog'!$E$51+'Assumptions and Catalog'!$F$51 -> 8279 | F51: =IF(AND(A51=$C$9,D51>B51,D51<=C51,D51>=0,ABS(E51-$C$8)<='Assumptions and Catalog'!$C$25),1,0) -> 0 | G51: =IF(F51=1,D51,0) -> 0
A52: ='Assumptions and Catalog'!$A$52 -> Residential | B52: ='Assumptions and Catalog'!$B$52 -> 50 | C52: ='Assumptions and Catalog'!$C$52 -> 100 | D52: =IF('Assumptions and Catalog'!$H$52=0,0,($C$8-'Assumptions and Catalog'!$E$52-'Assumptions and Catalog'!$F$52)/'Assumptions and Catalog'!$H$52) -> 9524.7126 | E52: =D52*'Assumptions and Catalog'!$H$52+'Assumptions and Catalog'!$E$52+'Assumptions and Catalog'!$F$52 -> 8279 | F52: =IF(AND(A52=$C$9,D52>B52,D52<=C52,D52>=0,ABS(E52-$C$8)<='Assumptions and Catalog'!$C$25),1,0) -> 0 | G52: =IF(F52=1,D52,0) -> 0
A53: ='Assumptions and Catalog'!$A$53 -> Residential | B53: ='Assumptions and Catalog'!$B$53 -> 100 | C53: ='Assumptions and Catalog'!$C$53 -> 200 | D53: =IF('Assumptions and Catalog'!$H$53=0,0,($C$8-'Assumptions and Catalog'!$E$53-'Assumptions and Catalog'!$F$53)/'Assumptions and Catalog'!$H$53) -> 8273 | E53: =D53*'Assumptions and Catalog'!$H$53+'Assumptions and Catalog'!$E$53+'Assumptions and Catalog'!$F$53 -> 8279 | F53: =IF(AND(A53=$C$9,D53>B53,D53<=C53,D53>=0,ABS(E53-$C$8)<='Assumptions and Catalog'!$C$25),1,0) -> 0 | G53: =IF(F53=1,D53,0) -> 0
A54: ='Assumptions and Catalog'!$A$54 -> Residential | B54: ='Assumptions and Catalog'!$B$54 -> 200 | C54: ='Assumptions and Catalog'!$C$54 -> 350 | D54: =IF('Assumptions and Catalog'!$H$54=0,0,($C$8-'Assumptions and Catalog'!$E$54-'Assumptions and Catalog'!$F$54)/'Assumptions and Catalog'!$H$54) -> 4863.5838 | E54: =D54*'Assumptions and Catalog'!$H$54+'Assumptions and Catalog'!$E$54+'Assumptions and Catalog'!$F$54 -> 8279 | F54: =IF(AND(A54=$C$9,D54>B54,D54<=C54,D54>=0,ABS(E54-$C$8)<='Assumptions and Catalog'!$C$25),1,0) -> 0 | G54: =IF(F54=1,D54,0) -> 0
A55: ='Assumptions and Catalog'!$A$55 -> Residential | B55: ='Assumptions and Catalog'!$B$55 -> 350 | C55: ='Assumptions and Catalog'!$C$55 -> 650 | D55: =IF('Assumptions and Catalog'!$H$55=0,0,($C$8-'Assumptions and Catalog'!$E$55-'Assumptions and Catalog'!$F$55)/'Assumptions and Catalog'!$H$55) -> 3930.0459 | E55: =D55*'Assumptions and Catalog'!$H$55+'Assumptions and Catalog'!$E$55+'Assumptions and Catalog'!$F$55 -> 8279 | F55: =IF(AND(A55=$C$9,D55>B55,D55<=C55,D55>=0,ABS(E55-$C$8)<='Assumptions and Catalog'!$C$25),1,0) -> 0 | G55: =IF(F55=1,D55,0) -> 0
A56: ='Assumptions and Catalog'!$A$56 -> Residential | B56: ='Assumptions and Catalog'!$B$56 -> 650 | C56: ='Assumptions and Catalog'!$C$56 -> 1000 | D56: =IF('Assumptions and Catalog'!$H$56=0,0,($C$8-'Assumptions and Catalog'!$E$56-'Assumptions and Catalog'!$F$56)/'Assumptions and Catalog'!$H$56) -> 3512.3404 | E56: =D56*'Assumptions and Catalog'!$H$56+'Assumptions and Catalog'!$E$56+'Assumptions and Catalog'!$F$56 -> 8279 | F56: =IF(AND(A56=$C$9,D56>B56,D56<=C56,D56>=0,ABS(E56-$C$8)<='Assumptions and Catalog'!$C$25),1,0) -> 0 | G56: =IF(F56=1,D56,0) -> 0
A57: ='Assumptions and Catalog'!$A$57 -> Residential | B57: ='Assumptions and Catalog'!$B$57 -> 1000 | C57: ='Assumptions and Catalog'!$C$57 -> 10000000 | D57: =IF('Assumptions and Catalog'!$H$57=0,0,($C$8-'Assumptions and Catalog'!$E$57-'Assumptions and Catalog'!$F$57)/'Assumptions and Catalog'!$H$57) -> 2850.8651 | E57: =D57*'Assumptions and Catalog'!$H$57+'Assumptions and Catalog'!$E$57+'Assumptions and Catalog'!$F$57 -> 8279 | F57: =IF(AND(A57=$C$9,D57>B57,D57<=C57,D57>=0,ABS(E57-$C$8)<='Assumptions and Catalog'!$C$25),1,0) -> 0 | G57: =IF(F57=1,D57,0) -> 0
A58: ='Assumptions and Catalog'!$A$60 -> Commercial | B58: ='Assumptions and Catalog'!$B$60 -> -1 | C58: ='Assumptions and Catalog'!$C$60 -> 0 | D58: =IF('Assumptions and Catalog'!$H$60=0,0,($C$8-'Assumptions and Catalog'!$E$60-'Assumptions and Catalog'!$F$60)/'Assumptions and Catalog'!$H$60) -> 0 | E58: =D58*'Assumptions and Catalog'!$H$60+'Assumptions and Catalog'!$E$60+'Assumptions and Catalog'!$F$60 -> 9 | F58: =IF(AND(A58=$C$9,D58>B58,D58<=C58,D58>=0,ABS(E58-$C$8)<='Assumptions and Catalog'!$C$25),1,0) -> 0 | G58: =IF(F58=1,D58,0) -> 0
A59: ='Assumptions and Catalog'!$A$61 -> Commercial | B59: ='Assumptions and Catalog'!$B$61 -> 0 | C59: ='Assumptions and Catalog'!$C$61 -> 100 | D59: =IF('Assumptions and Catalog'!$H$61=0,0,($C$8-'Assumptions and Catalog'!$E$61-'Assumptions and Catalog'!$F$61)/'Assumptions and Catalog'!$H$61) -> 5014.5455 | E59: =D59*'Assumptions and Catalog'!$H$61+'Assumptions and Catalog'!$E$61+'Assumptions and Catalog'!$F$61 -> 8279 | F59: =IF(AND(A59=$C$9,D59>B59,D59<=C59,D59>=0,ABS(E59-$C$8)<='Assumptions and Catalog'!$C$25),1,0) -> 0 | G59: =IF(F59=1,D59,0) -> 0
A60: ='Assumptions and Catalog'!$A$62 -> Commercial | B60: ='Assumptions and Catalog'!$B$62 -> 100 | C60: ='Assumptions and Catalog'!$C$62 -> 250 | D60: =IF('Assumptions and Catalog'!$H$62=0,0,($C$8-'Assumptions and Catalog'!$E$62-'Assumptions and Catalog'!$F$62)/'Assumptions and Catalog'!$H$62) -> 3773.516 | E60: =D60*'Assumptions and Catalog'!$H$62+'Assumptions and Catalog'!$E$62+'Assumptions and Catalog'!$F$62 -> 8279 | F60: =IF(AND(A60=$C$9,D60>B60,D60<=C60,D60>=0,ABS(E60-$C$8)<='Assumptions and Catalog'!$C$25),1,0) -> 0 | G60: =IF(F60=1,D60,0) -> 0
A61: ='Assumptions and Catalog'!$A$63 -> Commercial | B61: ='Assumptions and Catalog'!$B$63 -> 250 | C61: ='Assumptions and Catalog'!$C$63 -> 600 | D61: =IF('Assumptions and Catalog'!$H$63=0,0,($C$8-'Assumptions and Catalog'!$E$63-'Assumptions and Catalog'!$F$63)/'Assumptions and Catalog'!$H$63) -> 3093.2584 | E61: =D61*'Assumptions and Catalog'!$H$63+'Assumptions and Catalog'!$E$63+'Assumptions and Catalog'!$F$63 -> 8279 | F61: =IF(AND(A61=$C$9,D61>B61,D61<=C61,D61>=0,ABS(E61-$C$8)<='Assumptions and Catalog'!$C$25),1,0) -> 0 | G61: =IF(F61=1,D61,0) -> 0
A62: ='Assumptions and Catalog'!$A$64 -> Commercial | B62: ='Assumptions and Catalog'!$B$64 -> 600 | C62: ='Assumptions and Catalog'!$C$64 -> 1000 | D62: =IF('Assumptions and Catalog'!$H$64=0,0,($C$8-'Assumptions and Catalog'!$E$64-'Assumptions and Catalog'!$F$64)/'Assumptions and Catalog'!$H$64) -> 3001.444 | E62: =D62*'Assumptions and Catalog'!$H$64+'Assumptions and Catalog'!$E$64+'Assumptions and Catalog'!$F$64 -> 8279 | F62: =IF(AND(A62=$C$9,D62>B62,D62<=C62,D62>=0,ABS(E62-$C$8)<='Assumptions and Catalog'!$C$25),1,0) -> 0 | G62: =IF(F62=1,D62,0) -> 0
A63: ='Assumptions and Catalog'!$A$65 -> Commercial | B63: ='Assumptions and Catalog'!$B$65 -> 1000 | C63: ='Assumptions and Catalog'!$C$65 -> 10000000 | D63: =IF('Assumptions and Catalog'!$H$65=0,0,($C$8-'Assumptions and Catalog'!$E$65-'Assumptions and Catalog'!$F$65)/'Assumptions and Catalog'!$H$65) -> 2921.6312 | E63: =D63*'Assumptions and Catalog'!$H$65+'Assumptions and Catalog'!$E$65+'Assumptions and Catalog'!$F$65 -> 8279 | F63: =IF(AND(A63=$C$9,D63>B63,D63<=C63,D63>=0,ABS(E63-$C$8)<='Assumptions and Catalog'!$C$25),1,0) -> 1 | G63: =IF(F63=1,D63,0) -> 2921.6312
A66: Accepted solution count | C66: =SUM(F50:F63) -> 1

Sheet Assumptions and Catalog
A2: AVESTA — Assumptions and Catalog
A3: Yellow cells are editable. Equipment prices and limits are illustrative, not supplier quotes or manufacturer specifications.
A6: Study period | B6: years | C6: 10 | D6: 1 to 20
A7: Nominal discount rate | B7: % | C7: 0.1 | D7: Illustrative assumption; approval needed
A8: Tariff and fee escalation | B8: % per year | C8: 0 | D8: Flat by default; applies to all bill components
A9: Maintenance cost escalation | B9: % per year | C9: 0 | D9: Assumed cost escalation
A10: Annual PV degradation | B10: % per year | C10: 0.005 | D10: Assumption
A11: Charge efficiency | B11: % | C11: 0.975 | D11: AC input to stored energy
A12: Discharge efficiency | B12: % | C12: 0.975 | D12: Stored energy to AC load
A13: Daytime duration | B13: hours/day | C13: 12 | D13: Not PSH; used only to split daily load
A14: PV charging window | B14: hours/day | C14: 6 | D14: Approximate power window, not hourly simulation
A15: Grid charging window | B15: hours/day | C15: 8 | D15: Battery-only scenario
A16: Installation area multiplier | B16: times panel area | C16: 1.5 | D16: Includes assumed installation clearances
A17: Installation and BOS | B17: % of equipment | C17: 0.1 | D17: Applied once to PV, battery and inverter
... A26: Battery auxiliary consumption | B26: kWh/day | C26: 0 | D26: Not estimated; enter standby consumption
A29: Cairo average solar yield
A31: Average daily PV yield | B31: kWh/kWp/day | C31: 4.98 | D31: Monthly generation = PV kWp × daily yield × calendar days.
A33: 4.98 kWh/kWp/day is the rounded Cairo annual daily average from the previous PVGIS reference.
A34: Cairo; south-facing, 30° tilt. PV losses are included. No monthly solar seasonality is modeled.
A35: Source: European Commission JRC PVGIS 5.3 / SARAH3, prior project extract dated 30 September 2026.
A36: https://re.jrc.ec.europa.eu/pvg_tools/en/
A46: Editable reference tariff bands
A47: Tariffs from prior project files; current applicability could not be confirmed from the regulator link. Verify before commercial use.
A49: Type | B49: Above kWh | C49: Up to kWh | D49: Energy rate | E49: Energy intercept | F49: Service fee (EGP) | G49: Stamp/kWh | H49: Marginal rate incl. stamp
A50: Residential | B50: -1 | C50: 0 | D50: 0 | E50: 0 | F50: 9 | G50: 0 | H50: =D50+G50 -> 0
A51: Residential | B51: 0 | C51: 50 | D51: 0.68 | E51: 0 | F51: 1 | G51: 0 | H51: =D51+G51 -> 0.68
A52: Residential | B52: 50 | C52: 100 | D52: 0.87 | E52: =C51*D51-C51*D52 -> -9.5 | F52: 2 | G52: 0 | H52: =D52+G52 -> 0.87
A53: Residential | B53: 100 | C53: 200 | D53: 1 | E53: 0 | F53: 6 | G53: 0 | H53: =D53+G53 -> 1
A54: Residential | B54: 200 | C54: 350 | D54: 1.73 | E54: =C53*D53-C53*D54 -> -146 | F54: 11 | G54: 0 | H54: =D54+G54 -> 1.73
A55: Residential | B55: 350 | C55: 650 | D55: 2.18 | E55: =C54*D54+E54-C54*D55 -> -303.5 | F55: 15 | G55: 0 | H55: =D55+G55 -> 2.18
A56: Residential | B56: 650 | C56: 1000 | D56: 2.35 | E56: 0 | F56: 25 | G56: 0 | H56: =D56+G56 -> 2.35
A57: Residential | B57: 1000 | C57: 10000000 | D57: 2.89 | E57: 0 | F57: 40 | G57: 0 | H57: =D57+G57 -> 2.89
A60: Commercial | B60: -1 | C60: 0 | D60: 0 | E60: 0 | F60: 9 | G60: 0 | H60: =D60+G60 -> 0
A61: Commercial | B61: 0 | C61: 100 | D61: 1.62 | E61: 0 | F61: 5 | G61: 0.03 | H61: =D61+G61 -> 1.65
A62: Commercial | B62: 100 | C62: 250 | D62: 2.16 | E62: 0 | F62: 15 | G62: 0.03 | H62: =D62+G62 -> 2.19
A63: Commercial | B63: 250 | C63: 600 | D63: 2.64 | E63: 0 | F63: 20 | G63: 0.03 | H63: =D63+G63 -> 2.67
A64: Commercial | B64: 600 | C64: 1000 | D64: 2.74 | E64: =C63*D63-C63*D64 -> -60 | F64: 25 | G64: 0.03 | H64: =D64+G64 -> 2.77
A65: Commercial | B65: 1000 | C65: 10000000 | D65: 2.79 | E65: 0 | F65: 40 | G65: 0.03 | H65: =D65+G65 -> 2.82
A67: Residential rates: prior project model; service fees require confirmation. Commercial: prior El Mo3alem presentation (April 2026).
A68: https://www.egyptera.org/ar/TarrifApril2026.aspx — verification on 19 October 2026 returned 404. Annual stamp excluded.
...

Sheet Scenarios
A2: AVESTA — Scenario Comparison
A3: Three manually selected configurations. Financial results are indicative; no automatic size optimization.
A5: Metric | B5: Unit | C5: Solar only | D5: Battery only | E5: Solar and battery
A6: Configuration status | C6: =IF(C65=1,"Valid for indicative calculation","Check inputs / area / compatibility") -> Valid for indicative calculation | D6: =IF(D65=1,"Valid for indicative calculation","Check inputs / area / compatibility") -> Valid for indicative calculation | E6: =IF(E65=1,"Valid for indicative calculation","Check inputs / area / compatibility") -> Valid for indicative calculation
A7: PV capacity | B7: kWp | C7: =C51 -> 6.7 | D7: =D51 -> 0 | E7: =E51 -> 5.5 | H7: Equipment and quantities — edit yellow cells
A8: Nominal battery capacity | B8: kWh | C8: =C52 -> 0 | D8: =D52 -> 64 | E8: =E52 -> 160 | H8: Setting | I8: Unit | J8: Solar only | K8: Battery only | L8: Solar and battery
A9: Inverter capacity | B9: kW | C9: =C53 -> 10 | D9: =D53 -> 5 | E9: =E53 -> 12 | H9: Panel model | J9: PV670 | K9: PV550 | L9: PV550
A10: Required roof area | B10: m² | C10: =C59 -> 40.5 | D10: =D59 -> 0 | E10: =E59 -> 39 | H10: Panel quantity | J10: 10 | K10: 0 | L10: 10
A11: Initial investment | B11: EGP | C11: =C64 -> 124960 | D11: =D64 -> 993256 | E11: =E64 -> 2528240 | H11: Battery model | J11: BAT32 | K11: BAT32 | L11: BAT32
A12: Year 1 solar generation | B12: kWh | C12: =SUM(F161:F172) -> 12178.59 | D12: =SUM(F411:F422) -> 0 | E12: =SUM(F661:F672) -> 9997.35 | H12: Battery unit quantity | J12: 0 | K12: 2 | L12: 5
A13: Year 1 baseline bill | B13: EGP | C13: =$B$79 -> 100727.83 | D13: =$B$79 -> 100727.83 | E13: =$B$79 -> 100727.83 | H13: Inverter model | J13: GRID10 | K13: HYB5 | L13: HYB12
A14: Year 1 bill after installation | B14: EGP | C14: =IF(C65=1,SUM(N161:N172),"Invalid") -> 59081.18 | D14: =IF(D65=1,SUM(N411:N422),"Invalid") -> 100727.83 | E14: =IF(E65=1,SUM(N661:N672),"Invalid") -> 66540.282 | H14: Reserved share of usable capacity | I14: % | J14: 0.2 | K14: 1 | L14: 0.2
A15: Year 1 bill savings | B15: EGP | C15: =IF(C65=1,SUM(O161:O172),"Invalid") -> 41646.653 | D15: =IF(D65=1,SUM(O411:O422),"Invalid") -> 0 | E15: =IF(E65=1,SUM(O661:O672),"Invalid") -> 34187.551 | H15: Battery-only operating mode | J15: Backup | K15: Backup | L15: Backup
A16: Year 1 savings after maintenance | B16: EGP | C16: =IF(C65=1,C79,"Invalid") -> 40397.053 | D16: =IF(D65=1,G79,"Invalid") -> -9932.56 | E16: =IF(E65=1,K79,"Invalid") -> 8905.1509 | H16: Grid-charged delivery limit | I16: kWh/day | J16: 8 | K16: 8 | L16: 8
A17: NPV over study period | B17: EGP | C17: =IF(C65=1,SUM(D78:D98),"Invalid") -> 118751.58 | D17: =IF(D65=1,SUM(H78:H98),"Invalid") -> -1054287.3 | E17: =IF(E65=1,SUM(L78:L98),"Invalid") -> -2477224.6
A18: Simple payback | B18: years | C18: =IF(C65=0,"Invalid",IF(MIN(P79:P98)=999,"Not reached",MIN(P79:P98))) -> 3.1075781 | D18: =IF(D65=0,"Invalid",IF(MIN(R79:R98)=999,"Not reached",MIN(R79:R98))) -> Not reached | E18: =IF(E65=0,"Invalid",IF(MIN(T79:T98)=999,"Not reached",MIN(T79:T98))) -> Not reached | H18: Unused fields: battery for solar-only and PV for battery-only. Grid-cycle mode applies only to the battery-only column.
A19: Discounted payback | B19: years | C19: =IF(C65=0,"Invalid",IF(MIN(Q79:Q98)=999,"Not reached",MIN(Q79:Q98))) -> 3.9161381 | D19: =IF(D65=0,"Invalid",IF(MIN(S79:S98)=999,"Not reached",MIN(S79:S98))) -> Not reached | E19: =IF(E65=0,"Invalid",IF(MIN(U79:U98)=999,"Not reached",MIN(U79:U98))) -> Not reached
A20: Full-charge backup energy | B20: kWh AC | C20: =C68 -> 0 | D20: =D68 -> 49.92 | E20: =E68 -> 124.8
A21: Maximum backup power | B21: kW | C21: =C69 -> 0 | D21: =D69 -> 5 | E21: =E69 -> 12
A22: Backup hours from full charge | B22: hours | C22: =IF(C65=0,"Invalid",IF(C69=0,"Not available",IF(Inputs!$C$20="Unknown","Load unknown",IF(Inputs!$C$21>C69,"Load exceeds power limit",C68/Inputs!$C$21)))) -> Not available | D22: =IF(D65=0,"Invalid",IF(D69=0,"Not available",IF(Inputs!$C$20="Unknown","Load unknown",IF(Inputs!$C$21>D69,"Load exceeds power limit",D68/Inputs!$C$21)))) -> Load unknown | E22: =IF(E65=0,"Invalid",IF(E69=0,"Not available",IF(Inputs!$C$20="Unknown","Load unknown",IF(Inputs!$C$21>E69,"Load exceeds power limit",E68/Inputs!$C$21)))) -> Load unknown
A23: Reserved backup energy | B23: kWh AC | C23: =IF(C58=1,C67*'Assumptions and Catalog'!$C$12,0) -> 0 | D23: =IF(D58=1,D67*'Assumptions and Catalog'!$C$12,0) -> 49.92 | E23: =IF(E58=1,E67*'Assumptions and Catalog'!$C$12,0) -> 24.96
A24: System role | C24: =IF(C65=0,"Invalid",IF(C15>0,IF(C69>0,"Bill savings + backup capability","Bill savings"),IF(C69>0,"Backup capability, no bill savings","No bill savings demonstrated"))) -> Bill savings | D24: =IF(D65=0,"Invalid",IF(D15>0,IF(D69>0,"Bill savings + backup capability","Bill savings"),IF(D69>0,"Backup capability, no bill savings","No bill savings demonstrated"))) -> Backup capability, no bill savings | E24: =IF(E65=0,"Invalid",IF(E15>0,IF(E69>0,"Bill savings + backup capability","Bill savings"),IF(E69>0,"Backup capability, no bill savings","No bill savings demonstrated"))) -> Bill savings + backup capability
A25: Financial outcome | C25: =IF(C65=0,"Invalid",IF(C17>0,"Positive NPV under assumptions",IF(C17=0,"Discounted breakeven","Negative NPV under assumptions"))) -> Positive NPV under assumptions | D25: =IF(D65=0,"Invalid",IF(D17>0,"Positive NPV under assumptions",IF(D17=0,"Discounted breakeven","Negative NPV under assumptions"))) -> Negative NPV under assumptions | E25: =IF(E65=0,"Invalid",IF(E17>0,"Positive NPV under assumptions",IF(E17=0,"Discounted breakeven","Negative NPV under assumptions"))) -> Negative NPV under assumptions
A26: Roof area status | C26: =IF(Inputs!$C$14="Unspecified","Roof fit not verified",IF(C59<=Inputs!$C$15,"Within available area","Exceeds available area")) -> Roof fit not verified | D26: =IF(Inputs!$C$14="Unspecified","Roof fit not verified",IF(D59<=Inputs!$C$15,"Within available area","Exceeds available area")) -> Roof fit not verified | E26: =IF(Inputs!$C$14="Unspecified","Roof fit not verified",IF(E59<=Inputs!$C$15,"Within available area","Exceeds available area")) -> Roof fit not verified
A28: Full-charge backup is not guaranteed at outage time. Motor surge, load phase balance and site checks are not modeled.
A29: NPV excludes financing, taxes and outage value. The no-investment baseline has NPV = 0.
A31: Battery savings vs matched PV | B31: EGP/year | E31: =IF(E65=1,SUM(Q661:Q672)-SUM(N661:N672),"Invalid") -> 0
A32: Incremental battery investment | B32: EGP | E32: =E61*(1+'Assumptions and Catalog'!$C$17) -> 2400640
A33: Incremental comparison uses the same PV and hybrid inverter without a battery; no cheaper inverter alternative is assumed.
A50: Sizing and cost details
A51: Installed PV (kWp) | C51: =J10*INDEX('Assumptions and Catalog'!$C$73:$I$74,MATCH(J9,'Assumptions and Catalog'!$A$73:$A$74,0),1)/1000 -> 6.7 | D51: =0 -> 0 | E51: =L10*INDEX('Assumptions and Catalog'!$C$73:$I$74,MATCH(L9,'Assumptions and Catalog'!$A$73:$A$74,0),1)/1000 -> 5.5
A52: Nominal battery capacity (kWh) | C52: =0 -> 0 | D52: =K12*INDEX('Assumptions and Catalog'!$C$79:$I$81,MATCH(K11,'Assumptions and Catalog'!$A$79:$A$81,0),1) -> 64 | E52: =L12*INDEX('Assumptions and Catalog'!$C$79:$I$81,MATCH(L11,'Assumptions and Catalog'!$A$79:$A$81,0),1) -> 160
A53: Inverter AC rating (kW) | C53: =INDEX('Assumptions and Catalog'!$C$86:$I$89,MATCH(J13,'Assumptions and Catalog'!$A$86:$A$89,0),1) -> 10 | D53: =INDEX('Assumptions and Catalog'!$C$86:$I$89,MATCH(K13,'Assumptions and Catalog'!$A$86:$A$89,0),1) -> 5 | E53: =INDEX('Assumptions and Catalog'!$C$86:$I$89,MATCH(L13,'Assumptions and Catalog'!$A$86:$A$89,0),1) -> 12
A54: Inverter PV limit (kWp) | C54: =INDEX('Assumptions and Catalog'!$C$86:$I$89,MATCH(J13,'Assumptions and Catalog'!$A$86:$A$89,0),2) -> 13 | D54: =INDEX('Assumptions and Catalog'!$C$86:$I$89,MATCH(K13,'Assumptions and Catalog'!$A$86:$A$89,0),2) -> 6.5 | E54: =INDEX('Assumptions and Catalog'!$C$86:$I$89,MATCH(L13,'Assumptions and Catalog'!$A$86:$A$89,0),2) -> 15.6
A55: Usable internal capacity (kWh) | C55: =C52*INDEX('Assumptions and Catalog'!$C$79:$I$81,MATCH(J11,'Assumptions and Catalog'!$A$79:$A$81,0),2) -> 0 | D55: =D52*INDEX('Assumptions and Catalog'!$C$79:$I$81,MATCH(K11,'Assumptions and Catalog'!$A$79:$A$81,0),2) -> 51.2 | E55: =E52*INDEX('Assumptions and Catalog'!$C$79:$I$81,MATCH(L11,'Assumptions and Catalog'!$A$79:$A$81,0),2) -> 128
A56: Battery charge limit (AC kW) | C56: =MIN(J12*INDEX('Assumptions and Catalog'!$C$79:$I$81,MATCH(J11,'Assumptions and Catalog'!$A$79:$A$81,0),3),INDEX('Assumptions and Catalog'!$C$86:$I$89,MATCH(J13,'Assumptions and Catalog'!$A$86:$A$89,0),3)) -> 0 | D56: =MIN(K12*INDEX('Assumptions and Catalog'!$C$79:$I$81,MATCH(K11,'Assumptions and Catalog'!$A$79:$A$81,0),3),INDEX('Assumptions and Catalog'!$C$86:$I$89,MATCH(K13,'Assumptions and Catalog'!$A$86:$A$89,0),3)) -> 5 | E56: =MIN(L12*INDEX('Assumptions and Catalog'!$C$79:$I$81,MATCH(L11,'Assumptions and Catalog'!$A$79:$A$81,0),3),INDEX('Assumptions and Catalog'!$C$86:$I$89,MATCH(L13,'Assumptions and Catalog'!$A$86:$A$89,0),3)) -> 10
A57: Battery discharge limit (AC kW) | C57: =MIN(J12*INDEX('Assumptions and Catalog'!$C$79:$I$81,MATCH(J11,'Assumptions and Catalog'!$A$79:$A$81,0),4),C53) -> 0 | D57: =MIN(K12*INDEX('Assumptions and Catalog'!$C$79:$I$81,MATCH(K11,'Assumptions and Catalog'!$A$79:$A$81,0),4),D53) -> 5 | E57: =MIN(L12*INDEX('Assumptions and Catalog'!$C$79:$I$81,MATCH(L11,'Assumptions and Catalog'!$A$79:$A$81,0),4),E53) -> 12
A58: Backup supported 1/0 | C58: =0 -> 0 | D58: =INDEX('Assumptions and Catalog'!$C$86:$I$89,MATCH(K13,'Assumptions and Catalog'!$A$86:$A$89,0),4) -> 1 | E58: =INDEX('Assumptions and Catalog'!$C$86:$I$89,MATCH(L13,'Assumptions and Catalog'!$A$86:$A$89,0),4) -> 1
A59: Required area (m2) | C59: =C51*1000/INDEX('Assumptions and Catalog'!$C$73:$I$74,MATCH(J9,'Assumptions and Catalog'!$A$73:$A$74,0),1)*INDEX('Assumptions and Catalog'!$C$73:$I$74,MATCH(J9,'Assumptions and Catalog'!$A$73:$A$74,0),2)*'Assumptions and Catalog'!$C$16 -> 40.5 | D59: =D51*1000/INDEX('Assumptions and Catalog'!$C$73:$I$74,MATCH(K9,'Assumptions and Catalog'!$A$73:$A$74,0),1)*INDEX('Assumptions and Catalog'!$C$73:$I$74,MATCH(K9,'Assumptions and Catalog'!$A$73:$A$74,0),2)*'Assumptions and Catalog'!$C$16 -> 0 | E59: =E51*1000/INDEX('Assumptions and Catalog'!$C$73:$I$74,MATCH(L9,'Assumptions and Catalog'!$A$73:$A$74,0),1)*INDEX('Assumptions and Catalog'!$C$73:$I$74,MATCH(L9,'Assumptions and Catalog'!$A$73:$A$74,0),2)*'Assumptions and Catalog'!$C$16 -> 39
A60: PV panel cost (EGP) | C60: =C51*1000/INDEX('Assumptions and Catalog'!$C$73:$I$74,MATCH(J9,'Assumptions and Catalog'!$A$73:$A$74,0),1)*INDEX('Assumptions and Catalog'!$C$73:$I$74,MATCH(J9,'Assumptions and Catalog'!$A$73:$A$74,0),3) -> 53600 | D60: =D51*1000/INDEX('Assumptions and Catalog'!$C$73:$I$74,MATCH(K9,'Assumptions and Catalog'!$A$73:$A$74,0),1)*INDEX('Assumptions and Catalog'!$C$73:$I$74,MATCH(K9,'Assumptions and Catalog'!$A$73:$A$74,0),3) -> 0 | E60: =E51*1000/INDEX('Assumptions and Catalog'!$C$73:$I$74,MATCH(L9,'Assumptions and Catalog'!$A$73:$A$74,0),1)*INDEX('Assumptions and Catalog'!$C$73:$I$74,MATCH(L9,'Assumptions and Catalog'!$A$73:$A$74,0),3) -> 44000
...
